Workbook

Sheet 1
A1: Parking Survey Sheet
A3: Date: | B3: 46176
A4: Route #: | B4: Malatia Sebastia
A5: Name/Surname: | B5: _____________
A7: Time | B7: Zone | C7: License Number | D7: Vehicle Type | E7: Location | F7: Parking Method | G7: Legal/Illegal
A8: 7=7:00 14=14:00 midnight=00:00 & etc. | B8: Zone XXX | C8: 11XX111 | D8: C - Sedan T - Truck M - Motorcycle | E8: OS - On-Street FP - Footpath SB - Setback | F8: PA - Parallel A - 45 Degree PP - Perpendicular | G8: L - Legal I - Illegal
B13: No parking

Sheet 2
A1: Parking Survey Sheet
A3: Date: | B3: 46176
A4: Route #: | B4: Malatia Sebastia
A5: Name/Surname: | B5: _____________
A7: Time | B7: Zone | C7: License Number | D7: Vehicle Type | E7: Location | F7: Parking Method | G7: Legal/Illegal
A8: 7=7:00 14=14:00 midnight=00:00 & etc. | B8: Zone XXX | C8: 11XX111 | D8: C - Sedan T - Truck M - Motorcycle | E8: OS - On-Street FP - Footpath SB - Setback | F8: PA - Parallel A - 45 Degree PP - Perpendicular | G8: L - Legal I - Illegal
A9: 7 - 8 | B9: 2 | C9: 33 PP 640 | D9: C - Sedan | E9: OS - On-Street | F9: A - 45 Degree | G9: L
B10: 2 | C10: 71 KK 007 | D10: C - Sedan | E10: OS - On-Street | F10: A - 45 Degree | G10: L
B11: 2 | C11: 37HR434 | D11: C - Sedan | E11: OS - On-Street | F11: PA - Parallel | G11: L
A12: 8 - 9 | B12: 2 | C12: 34CT380 | D12: C - Sedan | E12: FP - Footpath | F12: PA - Parallel | G12: L
B13: 2 | C13: 70PO070 | D13: C - Sedan | E13: FP - Footpath | F13: A - 45 Degree | G13: L
B14: 2 | C14: 22DD220 | D14: C - Sedan | E14: FP - Footpath | F14: A - 45 Degree | G14: L
B15: 2 | C15: 37JK738 | D15: C - Sedan | E15: FP - Footpath | F15: A - 45 Degree | G15: L
B16: 2 | C16: 91SM009 | D16: C - Sedan | E16: OS - On-Street | F16: A - 45 Degree | G16: L
B17: 2 | C17: 36VU470 | D17: C - Sedan | E17: FP - Footpath | F17: A - 45 Degree | G17: L
B18: 2 | C18: 626CZ61 | D18: C - Sedan | E18: FP - Footpath | F18: PA - Parallel | G18: L
B19: 2 | C19: 37EG610 | D19: C - Sedan | E19: FP - Footpath | F19: PA - Parallel | G19: L
B20: 2 | C20: 139CR61 | D20: C - Sedan | E20: FP - Footpath | F20: PA - Parallel | G20: L
B21: 2 | C21: 37JU422 | D21: C - Sedan | E21: FP - Footpath | F21: PA - Parallel | G21: L
B22: 2 | C22: 37AD629 | D22: C - Sedan | E22: FP - Footpath | F22: PA - Parallel | G22: L
B23: 2 | C23: 77ZJ779 | D23: C - Sedan | E23: FP - Footpath | F23: PA - Parallel | G23: L
B24: 2 | C24: 88DW888 | D24: C - Sedan | E24: FP - Footpath | F24: PA - Parallel | G24: L
... B27: 2 | C27: 37DY100 | D27: C - Sedan | E27: FP - Footpath | F27: PA - Parallel | G27: L
A28: 9 - 10 | B28: 2 | C28: 37PW217 | D28: C - Sedan | E28: OS - On-Street | F28: A - 45 Degree | G28: L
B29: 2 | C29: 34CT380 | D29: C - Sedan | E29: SB - Setback | F29: A - 45 Degree | G29: L
B30: 2 | C30: 22DD220 | D30: C - Sedan | E30: SB - Setback | F30: A - 45 Degree | G30: L
B31: 2 | C31: 02SH025 | D31: C - Sedan | E31: SB - Setback | F31: A - 45 Degree | G31: L
B32: 2 | C32: 71TR700 | D32: C - Sedan | E32: SB - Setback | F32: A - 45 Degree | G32: L
B33: 2 | C33: 29LS776 | D33: C - Sedan | E33: SB - Setback | F33: A - 45 Degree | G33: L
B34: 2 | C34: 77ZJ779 | D34: T - Truck | E34: SB - Setback | F34: A - 45 Degree | G34: L
B35: 2 | C35: 37AD692 | D35: C - Sedan | E35: SB - Setback | F35: PP - Perpendicular | G35: L
B36: 2 | C36: 88DW888 | D36: C - Sedan | E36: SB - Setback | F36: PP - Perpendicular | G36: L
B37: 2 | C37: 37TU006 | D37: C - Sedan | E37: SB - Setback | F37: PP - Perpendicular | G37: L
B38: 2 | C38: 33AB333 | D38: C - Sedan | E38: SB - Setback | F38: PP - Perpendicular | G38: L
B39: 2 | C39: 37UC619 | D39: C - Sedan | E39: SB - Setback | F39: PP - Perpendicular | G39: L
A40: 10 - 11 | B40: 2 | C40: 76KP318 | D40: C - Sedan | E40: OS - On-Street | F40: PA - Parallel | G40: L
B41: 2 | C41: 12MX907 | D41: C - Sedan | E41: OS - On-Street | F41: PA - Parallel | G41: L
B42: 2 | C42: 33FF353 | D42: C - Sedan | E42: OS - On-Street | F42: PA - Parallel | G42: L
B43: 2 | C43: 300QQ13 | D43: C - Sedan | E43: OS - On-Street | F43: PA - Parallel | G43: L
B44: 2 | C44: 85BB588 | D44: C - Sedan | E44: OS - On-Street | F44: PA - Parallel | G44: L
...

Sheet 3
A1: Parking Survey Sheet
A3: Date: | B3: 46176
A4: Route #: | B4: Malatia Sebastia
A5: Name/Surname: | B5: _____________
A7: Time | B7: Zone | C7: License Number | D7: Vehicle Type | E7: Location | F7: Parking Method | G7: Legal/Illegal
A8: 7=7:00 14=14:00 midnight=00:00 & etc. | B8: Zone XXX | C8: 11XX111 | D8: C - Sedan T - Truck M - Motorcycle | E8: OS - On-Street FP - Footpath SB - Setback | F8: PA - Parallel A - 45 Degree PP - Perpendicular | G8: L - Legal I - Illegal
A9: 7 - 8 | B9: 3 | C9: 34 MA 086 | D9: C - Sedan | E9: OS - On-Street | F9: A - 45 Degree | G9: L
B10: 3 | C10: 10 YY 202 | D10: C - Sedan | E10: OS - On-Street | F10: A - 45 Degree | G10: L
B11: 3 | C11: 35TN476 | D11: C - Sedan | E11: OS - On-Street | F11: PA - Parallel | G11: L
B12: 3 | C12: 35UD535 | D12: C - Sedan | E12: OS - On-Street | F12: PA - Parallel | G12: L
A13: 8 - 9 | B13: 3 | C13: 80MN878 | D13: C - Sedan | E13: OS - On-Street | F13: A - 45 Degree | G13: L
B14: 3 | C14: 01TO077 | D14: C - Sedan | E14: OS - On-Street | F14: A - 45 Degree | G14: L
B15: 3 | C15: 50HS100 | D15: C - Sedan | E15: FP - Footpath | F15: A - 45 Degree | G15: L
B16: 3 | C16: 35TO445 | D16: C - Sedan | E16: FP - Footpath | F16: A - 45 Degree | G16: L
B17: 3 | C17: 04RR914 | D17: C - Sedan | E17: FP - Footpath | F17: A - 45 Degree | G17: L
B18: 3 | C18: 37QB492 | D18: T - Truck | E18: FP - Footpath | F18: A - 45 Degree | G18: L
B19: 3 | C19: 89OO008 | D19: C - Sedan | E19: FP - Footpath | F19: A - 45 Degree | G19: L
B20: 3 | C20: 37KV838 | D20: C - Sedan | E20: FP - Footpath | F20: A - 45 Degree | G20: L
B21: 3 | C21: 10AG019 | D21: C - Sedan | E21: FP - Footpath | F21: A - 45 Degree | G21: L
B22: 3 | C22: 37ET080 | D22: C - Sedan | E22: FP - Footpath | F22: A - 45 Degree | G22: L
B23: 3 | C23: 91PV001 | D23: C - Sedan | E23: FP - Footpath | F23: A - 45 Degree | G23: L
B24: 3 | C24: 44DU440 | D24: C - Sedan | E24: FP - Footpath | F24: A - 45 Degree | G24: L
B25: 3 | C25: 01PP991 | D25: C - Sedan | E25: FP - Footpath | F25: A - 45 Degree | G25: L
B26: 3 | C26: 37KA677 | D26: C - Sedan | E26: FP - Footpath | F26: A - 45 Degree | G26: L
A27: 9 - 10 | B27: 3 | C27: 37UQ477 | D27: C - Sedan | E27: SB - Setback | F27: PA - Parallel | G27: L
B28: 3 | C28: 80NN878 | D28: C - Sedan | E28: OS - On-Street | F28: A - 45 Degree | G28: L
B29: 3 | C29: 35RZ972 | D29: C - Sedan | E29: OS - On-Street | F29: A - 45 Degree | G29: L
B30: 3 | C30: 01TO077 | D30: C - Sedan | E30: OS - On-Street | F30: A - 45 Degree | G30: L
B31: 3 | C31: 91HA555 | D31: C - Sedan | E31: OS - On-Street | F31: A - 45 Degree | G31: L
B32: 3 | C32: 50HS100 | D32: C - Sedan | E32: OS - On-Street | F32: A - 45 Degree | G32: L
B33: 3 | C33: 37RH996 | D33: C - Sedan | E33: OS - On-Street | F33: A - 45 Degree | G33: L
B34: 3 | C34: 35TO445 | D34: C - Sedan | E34: OS - On-Street | F34: A - 45 Degree | G34: L
B35: 3 | C35: 81EE333 | D35: C - Sedan | E35: OS - On-Street | F35: A - 45 Degree | G35: L
B36: 3 | C36: 37QB492 | D36: C - Sedan | E36: OS - On-Street | F36: A - 45 Degree | G36: L
B37: 3 | C37: 89OO008 | D37: C - Sedan | E37: OS - On-Street | F37: A - 45 Degree | G37: L
B38: 3 | C38: 12IT221 | D38: C - Sedan | E38: OS - On-Street | F38: A - 45 Degree | G38: L
B39: 3 | C39: 10AG019 | D39: C - Sedan | E39: OS - On-Street | F39: A - 45 Degree | G39: L
B40: 3 | C40: 10ZW110 | D40: C - Sedan | E40: OS - On-Street | F40: A - 45 Degree | G40: L
A41: 10 - 11 | B41: 3 | C41: 69XE152 | D41: C - Sedan | E41: OS - On-Street | F41: PA - Parallel | G41: L
B42: 3 | C42: 18AB794 | D42: C - Sedan | E42: OS - On-Street | F42: PA - Parallel | G42: L
...

Sheet 4
A1: Parking Survey Sheet
A3: Date: | B3: 46176
A4: Route #: | B4: Malatia Sebastia
A5: Name/Surname: | B5: _____________
A7: Time | B7: Zone | C7: License Number | D7: Vehicle Type | E7: Location | F7: Parking Method | G7: Legal/Illegal
A8: 7=7:00 14=14:00 midnight=00:00 & etc. | B8: Zone XXX | C8: 11XX111 | D8: C - Sedan T - Truck M - Motorcycle | E8: OS - On-Street FP - Footpath SB - Setback | F8: PA - Parallel A - 45 Degree PP - Perpendicular | G8: L - Legal I - Illegal
A9: 7 - 8 | B9: 4 | C9: 95LG900 | D9: C - Sedan | E9: OS - On-Street | F9: PA - Parallel | G9: L
B10: 4 | C10: 71KK007 | D10: C - Sedan | E10: FP - Footpath | F10: PA - Parallel | G10: L
B11: 4 | C11: 34LP439 | D11: T - Truck | E11: OS - On-Street | F11: PA - Parallel | G11: L
B12: 4 | C12: 35AC412 | D12: C - Sedan | E12: OS - On-Street | F12: PA - Parallel | G12: L
A13: 8 - 9 | B13: 4 | C13: 37DW758 | D13: C - Sedan | E13: OS - On-Street | F13: PA - Parallel | G13: L
B14: 4 | C14: 37JX156 | D14: C - Sedan | E14: OS - On-Street | F14: PA - Parallel | G14: L
B15: 4 | C15: H298TC09 | D15: C - Sedan | E15: OS - On-Street | F15: PP - Perpendicular | G15: L
B16: 4 | C16: 22LL796 | D16: T - Truck | E16: OS - On-Street | F16: PP - Perpendicular | G16: L
B17: 4 | C17: 12DA333 | D17: C - Sedan | E17: OS - On-Street | F17: PP - Perpendicular | G17: L
B18: 4 | C18: 10OS202 | D18: T - Truck | E18: OS - On-Street | F18: PA - Parallel | G18: L
B19: 4 | C19: 35AM862 | D19: C - Sedan | E19: OS - On-Street | F19: PA - Parallel | G19: L
B20: 4 | C20: 88CR880 | D20: C - Sedan | E20: OS - On-Street | F20: PP - Perpendicular | G20: L
B21: 4 | C21: 37PB439 | D21: C - Sedan | E21: OS - On-Street | F21: PP - Perpendicular | G21: L
B22: 4 | C22: 57XP057 | D22: T - Truck | E22: OS - On-Street | F22: PP - Perpendicular | G22: L
B23: 4 | C23: 36QO560 | D23: C - Sedan | E23: OS - On-Street | F23: A - 45 Degree | G23: L
B24: 4 | C24: 37VA502 | D24: C - Sedan | E24: OS - On-Street | F24: PA - Parallel | G24: L
B25: 4 | C25: 37NV467 | D25: C - Sedan | E25: OS - On-Street | F25: PA - Parallel | G25: L
B26: 4 | C26: 78QA778 | D26: T - Truck | E26: OS - On-Street | F26: PA - Parallel | G26: L
A27: 9 - 10 | B27: 4 | C27: 72TT707 | D27: C - Sedan | E27: OS - On-Street | F27: A - 45 Degree | G27: L
B28: 4 | C28: 44DU440 | D28: C - Sedan | E28: OS - On-Street | F28: A - 45 Degree | G28: L
B29: 4 | C29: 66PT606 | D29: C - Sedan | E29: OS - On-Street | F29: A - 45 Degree | G29: L
B30: 4 | C30: 37KA677 | D30: C - Sedan | E30: OS - On-Street | F30: A - 45 Degree | G30: L
B31: 4 | C31: 37DW758 | D31: C - Sedan | E31: OS - On-Street | F31: PA - Parallel | G31: L
B32: 4 | C32: Н298ТС09 | D32: C - Sedan | E32: FP - Footpath | F32: A - 45 Degree | G32: L
B33: 4 | C33: 22LL796 | D33: C - Sedan | E33: FP - Footpath | F33: A - 45 Degree | G33: L
B34: 4 | C34: 33OP640 | D34: C - Sedan | E34: OS - On-Street | F34: PP - Perpendicular | G34: L
B35: 4 | C35: 10YY202 | D35: C - Sedan | E35: OS - On-Street | F35: PP - Perpendicular | G35: L
B36: 4 | C36: 10OS202 | D36: T - Truck | E36: FP - Footpath | F36: PP - Perpendicular | G36: L
B37: 4 | C37: 37SE738 | D37: C - Sedan | E37: FP - Footpath | F37: A - 45 Degree | G37: L
B38: 4 | C38: ZO700AB | D38: C - Sedan | E38: OS - On-Street | F38: PA - Parallel | G38: L
B39: 4 | C39: 37PB439 | D39: C - Sedan | E39: OS - On-Street | F39: PP - Perpendicular | G39: L
... B42: 4 | C42: 36GM896 | D42: C - Sedan | E42: FP - Footpath | F42: PA - Parallel | G42: L
A43: 10 - 11 | B43: 4 | C43: 20BE615 | D43: C - Sedan | E43: OS - On-Street | F43: PA - Parallel | G43: L
B44: 4 | C44: 10BW200 | D44: C - Sedan | E44: OS - On-Street | F44: PA - Parallel | G44: L
...

Sheet 5
A1: Parking Survey Sheet
A3: Date: | B3: 46176
A4: Route #: | B4: Malatia Sebastia
A5: Name/Surname: | B5: _____________
A7: Time | B7: Zone | C7: License Number | D7: Vehicle Type | E7: Location | F7: Parking Method | G7: Legal/Illegal
A8: 7=7:00 14=14:00 midnight=00:00 & etc. | B8: Zone XXX | C8: 11XX111 | D8: C - Sedan T - Truck M - Motorcycle | E8: OS - On-Street FP - Footpath SB - Setback | F8: PA - Parallel A - 45 Degree PP - Perpendicular | G8: L - Legal I - Illegal
A9: 7 - 8 | B9: 5 | C9: 37 DV 758 | D9: C - Sedan | E9: OS - On-Street | F9: A - 45 Degree | G9: L
B10: 5 | C10: 36 AC 540 | D10: C - Sedan | E10: OS - On-Street | F10: A - 45 Degree | G10: L
B11: 5 | C11: 06CG606 | D11: T - Truck | E11: OS - On-Street | F11: PA - Parallel | G11: L
A12: 8 - 9 | B12: 5 | C12: 91ZI001 | D12: C - Sedan | E12: OS - On-Street | F12: A - 45 Degree | G12: L
B13: 5 | C13: 37UZ646 | D13: C - Sedan | E13: OS - On-Street | F13: A - 45 Degree | G13: L
B14: 5 | C14: 47GQ007 | D14: C - Sedan | E14: OS - On-Street | F14: A - 45 Degree | G14: L
B15: 5 | C15: 10CD001 | D15: C - Sedan | E15: OS - On-Street | F15: PP - Perpendicular | G15: L
B16: 5 | C16: 37KV776 | D16: C - Sedan | E16: OS - On-Street | F16: A - 45 Degree | G16: L
B17: 5 | C17: 87UT777 | D17: C - Sedan | E17: OS - On-Street | F17: A - 45 Degree | G17: L
B18: 5 | C18: 706LS61 | D18: T - Truck | E18: OS - On-Street | F18: A - 45 Degree | G18: L
B19: 5 | C19: 97VF999 | D19: T - Truck | E19: OS - On-Street | F19: A - 45 Degree | G19: L
B20: 5 | C20: 71AA700 | D20: T - Truck | E20: OS - On-Street | F20: A - 45 Degree | G20: L
A21: 9 - 10 | B21: 5 | C21: 37PN451 | D21: C - Sedan | E21: OS - On-Street | F21: A - 45 Degree | G21: L
B22: 5 | C22: 092DG61 | D22: T - Truck | E22: OS - On-Street | F22: A - 45 Degree | G22: L
B23: 5 | C23: 843DE61 | D23: T - Truck | E23: OS - On-Street | F23: A - 45 Degree | G23: L
B24: 5 | C24: 36TG422 | D24: C - Sedan | E24: OS - On-Street | F24: PA - Parallel | G24: L
B25: 5 | C25: 35AA153 | D25: T - Truck | E25: OS - On-Street | F25: A - 45 Degree | G25: L
B26: 5 | C26: 35MC070 | D26: C - Sedan | E26: FP - Footpath | F26: A - 45 Degree | G26: L
B27: 5 | C27: 37FC395 | D27: T - Truck | E27: FP - Footpath | F27: A - 45 Degree | G27: L
B28: 5 | C28: 88TW808 | D28: C - Sedan | E28: OS - On-Street | F28: A - 45 Degree | G28: L
B29: 5 | C29: 10CD001 | D29: C - Sedan | E29: OS - On-Street | F29: PP - Perpendicular | G29: L
B30: 5 | C30: 87UT777 | D30: C - Sedan | E30: OS - On-Street | F30: PP - Perpendicular | G30: L
A31: 10 - 11 | B31: 5 | C31: 36KM127 | D31: C - Sedan | E31: OS - On-Street | F31: PA - Parallel | G31: L
B32: 5 | C32: 90NT563 | D32: C - Sedan | E32: OS - On-Street | F32: PA - Parallel | G32: L
B33: 5 | C33: 24OV890 | D33: C - Sedan | E33: OS - On-Street | F33: PA - Parallel | G33: L
B34: 5 | C34: 57PX241 | D34: C - Sedan | E34: OS - On-Street | F34: PA - Parallel | G34: L
A35: 11 - 12 | B35: 5 | C35: 91ZI001 | D35: C - Sedan | E35: FP - Footpath | F35: PA - Parallel | G35: L
B36: 5 | C36: 01AQ911 | D36: C - Sedan | E36: FP - Footpath | F36: PA - Parallel | G36: L
B37: 5 | C37: 88TW808 | D37: C - Sedan | E37: FP - Footpath | F37: A - 45 Degree | G37: L
B38: 5 | C38: 010OI10 | D38: C - Sedan | E38: FP - Footpath | F38: A - 45 Degree | G38: L
B39: 5 | C39: 37KV776 | D39: C - Sedan | E39: FP - Footpath | F39: A - 45 Degree | G39: L
A40: 12 - 13 | B40: 5 | C40: 36ZR902 | D40: C - Sedan | E40: OS - On-Street | F40: A - 45 Degree | G40: L
B41: 5 | C41: 007HH70 | D41: C - Sedan | E41: OS - On-Street | F41: PP - Perpendicular | G41: L
B42: 5 | C42: 36RA845 | D42: C - Sedan | E42: OS - On-Street | F42: PP - Perpendicular | G42: L
...

Sheet 6
A1: Parking Survey Sheet
A3: Date: | B3: 46176
A4: Route #: | B4: Malatia Sebastia
A5: Name/Surname: | B5: _____________
A7: Time | B7: Zone | C7: License Number | D7: Vehicle Type | E7: Location | F7: Parking Method | G7: Legal/Illegal
A8: 7=7:00 14=14:00 midnight=00:00 & etc. | B8: Zone XXX | C8: 11XX111 | D8: C - Sedan T - Truck M - Motorcycle | E8: OS - On-Street FP - Footpath SB - Setback | F8: PA - Parallel A - 45 Degree PP - Perpendicular | G8: L - Legal I - Illegal
A9: 7 - 8 | B9: 6 | C9: 37 GJ 509 | D9: C - Sedan | E9: OS - On-Street | F9: A - 45 Degree | G9: L
B10: 6 | C10: FP510PP | D10: T - Truck | E10: FP - Footpath | F10: A - 45 Degree | G10: L
A11: 8 -9 | B11: 6 | C11: 37FL804 | D11: C - Sedan | E11: OS - On-Street | F11: A - 45 Degree | G11: L
B12: 6 | C12: 37PY597 | D12: C - Sedan | E12: OS - On-Street | F12: A - 45 Degree | G12: L
B13: 6 | C13: 77XR771 | D13: T - Truck | E13: OS - On-Street | F13: A - 45 Degree | G13: L
B14: 6 | C14: 88GC006 | D14: T - Truck | E14: OS - On-Street | F14: A - 45 Degree | G14: L
B15: 6 | C15: 85ZA500 | D15: T - Truck | E15: OS - On-Street | F15: A - 45 Degree | G15: L
B16: 6 | C16: 80HH111 | D16: T - Truck | E16: OS - On-Street | F16: A - 45 Degree | G16: L
B17: 6 | C17: 159HS61 | D17: T - Truck | E17: OS - On-Street | F17: A - 45 Degree | G17: L
B18: 6 | C18: 05CH055 | D18: C - Sedan | E18: OS - On-Street | F18: A - 45 Degree | G18: L
B19: 6 | C19: 99BD996 | D19: C - Sedan | E19: OS - On-Street | F19: A - 45 Degree | G19: L
A20: 9 - 10 | B20: 6 | C20: 80HH111 | D20: T - Truck | E20: SB - Setback | F20: A - 45 Degree | G20: L
B21: 6 | C21: 159HS61 | D21: T - Truck | E21: OS - On-Street | F21: A - 45 Degree | G21: L
B22: 6 | C22: 05CH055 | D22: C - Sedan | E22: OS - On-Street | F22: A - 45 Degree | G22: L
C23: 88PS886 | D23: C - Sedan | E23: OS - On-Street | F23: A - 45 Degree | G23: L
B24: 6 | C24: 57XP057 | D24: T - Truck | E24: SB - Setback | F24: A - 45 Degree | G24: L
B25: 6 | C25: 99BD996 | D25: T - Truck | E25: SB - Setback | F25: A - 45 Degree | G25: L
A26: 10 - 11 | B26: 6 | C26: 70NP700 | D26: C - Sedan | E26: OS - On-Street | F26: A - 45 Degree | G26: L
B27: 6 | C27: 50QS500 | D27: C - Sedan | E27: OS - On-Street | F27: A - 45 Degree | G27: L
B28: 6 | C28: 88AY886 | D28: C - Sedan | E28: OS - On-Street | F28: A - 45 Degree | G28: L
B29: 6 | C29: 37FL804 | D29: C - Sedan | E29: OS - On-Street | F29: A - 45 Degree | G29: L
A30: 11 - 12 | B30: 6 | C30: 35VO909 | D30: C - Sedan | E30: OS - On-Street | F30: A - 45 Degree | G30: L
B31: 6 | C31: 888TT08 | D31: C - Sedan | E31: FP - Footpath | F31: A - 45 Degree | G31: L
B32: 6 | C32: 99BD996 | D32: T - Truck | E32: FP - Footpath | F32: A - 45 Degree | G32: L
A33: 12 - 13 | B33: 6 | C33: 20OY020 | D33: C - Sedan | E33: OS - On-Street | F33: PP - Perpendicular | G33: L
B34: 6 | C34: 36VO617 | D34: C - Sedan | E34: OS - On-Street | F34: PP - Perpendicular | G34: L
B35: 6 | C35: 36PA598 | D35: C - Sedan | E35: OS - On-Street | F35: PP - Perpendicular | G35: L
A36: 13 - 14 | B36: 6 | C36: 03AG033 | D36: C - Sedan | E36: OS - On-Street | F36: PP - Perpendicular | G36: L
B37: 6 | C37: 07LD707 | D37: C - Sedan | E37: OS - On-Street | F37: PP - Perpendicular | G37: L
B38: 6 | C38: 91EH001 | D38: T - Truck | E38: OS - On-Street | F38: PP - Perpendicular | G38: L
A39: 14 - 15 | B39: 6 | C39: 20OY020 | D39: C - Sedan | E39: OS - On-Street | F39: PP - Perpendicular | G39: L
B40: 6 | C40: 36PA598 | D40: C - Sedan | E40: OS - On-Street | F40: PP - Perpendicular | G40: L
A41: 15 - 16 | B41: 6 | C41: 70II505 | D41: C - Sedan | E41: FP - Footpath | F41: PP - Perpendicular | G41: L
B42: 6 | C42: 37SA179 | D42: C - Sedan | E42: FP - Footpath | F42: PP - Perpendicular | G42: L
...

Sheet 7
A1: Parking Survey Sheet
A3: Date: | B3: 46176
A4: Route #: | B4: Malatia Sebastia
A5: Name/Surname: | B5: _____________
A7: Time | B7: Zone | C7: License Number | D7: Vehicle Type | E7: Location | F7: Parking Method | G7: Legal/Illegal
A8: 7=7:00 14=14:00 midnight=00:00 & etc. | B8: Zone XXX | C8: 11XX111 | D8: C - Sedan T - Truck M - Motorcycle | E8: OS - On-Street FP - Footpath SB - Setback | F8: PA - Parallel A - 45 Degree PP - Perpendicular | G8: L - Legal I - Illegal
A9: 7 - 8 | B9: 7 | C9: 07 OO 372 | D9: C - Sedan | E9: OS - On-Street | F9: A - 45 Degree | G9: L
B10: 7 | C10: 05 VL 011 | D10: C - Sedan | E10: OS - On-Street | F10: A - 45 Degree | G10: L
A11: 8 - 9 | B11: 7 | C11: 40LQ040 | D11: C - Sedan | E11: OS - On-Street | F11: PA - Parallel | G11: L
B12: 7 | C12: 07RM070 | D12: C - Sedan | E12: OS - On-Street | F12: PA - Parallel | G12: L
B13: 7 | C13: 35VY035 | D13: C - Sedan | E13: OS - On-Street | F13: PA - Parallel | G13: L
B14: 7 | C14: 20aOY020 | D14: C - Sedan | E14: OS - On-Street | F14: PA - Parallel | G14: L
B15: 7 | C15: 27SO669 | D15: C - Sedan | E15: OS - On-Street | F15: PA - Parallel | G15: L
A16: 9 - 10 | B16: 7 | C16: 09XB099 | D16: T - Truck | E16: OS - On-Street | F16: PA - Parallel | G16: L
B17: 7 | C17: 40LG040 | D17: C - Sedan | E17: OS - On-Street | F17: PA - Parallel | G17: L
B18: 7 | C18: 99BS996 | D18: C - Sedan | E18: OS - On-Street | F18: PA - Parallel | G18: L
B19: 7 | C19: 07RM070 | D19: T - Truck | E19: OS - On-Street | F19: PA - Parallel | G19: L
B20: 7 | C20: 37FG900 | D20: C - Sedan | E20: FP - Footpath | F20: A - 45 Degree | G20: L
B21: 7 | C21: 27SO699 | D21: T - Truck | E21: OS - On-Street | F21: PA - Parallel | G21: L
A22: 10 - 11 | B22: 7 | C22: 51TA551 | D22: C - Sedan | E22: FP - Footpath | F22: A - 45 Degree | G22: L
B23: 7 | C23: UF597UU | D23: C - Sedan | E23: OS - On-Street | F23: PA - Parallel | G23: L
B24: 7 | C24: 37UF117 | D24: C - Sedan | E24: OS - On-Street | F24: PA - Parallel | G24: L
B25: 7 | C25: 10XC101 | D25: C - Sedan | E25: OS - On-Street | F25: PA - Parallel | G25: L
A26: 11 - 12 | B26: 7 | C26: 37EU332 | D26: C - Sedan | E26: FP - Footpath | F26: PA - Parallel | G26: L
B27: 7 | C27: 99BS996 | D27: C - Sedan | E27: FP - Footpath | F27: PA - Parallel | G27: L
B28: 7 | C28: 37FG900 | D28: C - Sedan | E28: FP - Footpath | F28: PA - Parallel | G28: L
B29: 7 | C29: 20OY020 | D29: C - Sedan | E29: FP - Footpath | F29: A - 45 Degree | G29: L
A30: 12 - 13 | B30: 7 | C30: 36MS460 | D30: C - Sedan | E30: OS - On-Street | F30: A - 45 Degree | G30: L
B31: 7 | C31: 88HU888 | D31: C - Sedan | E31: OS - On-Street | F31: A - 45 Degree | G31: L
A32: 13 - 14 | B32: 7 | C32: 35UZ111 | D32: C - Sedan | E32: OS - On-Street | F32: PA - Parallel | G32: L
B33: 7 | C33: 29TT555 | D33: C - Sedan | E33: OS - On-Street | F33: PA - Parallel | G33: L
B34: 7 | C34: 37MO995 | D34: C - Sedan | E34: OS - On-Street | F34: PA - Parallel | G34: L
A35: 14 - 15 | C35: 50IB101 | D35: C - Sedan | E35: OS - On-Street | F35: PA - Parallel | G35: L
B36: 7 | C36: 88HU888 | D36: C - Sedan | E36: OS - On-Street | F36: A - 45 Degree | G36: L
A37: 15 - 16 | B37: 7 | C37: 50IW150 | D37: C - Sedan | E37: OS - On-Street | F37: PA - Parallel | G37: L
B38: 7 | C38: 73HA777 | D38: C - Sedan | E38: FP - Footpath | F38: PA - Parallel | G38: L
A39: 16 - 17 | B39: 7 | C39: 35 RX 312 | D39: C - Sedan | E39: OS - On-Street | F39: PP - Perpendicular | G39: L
B40: 7 | C40: 37 TF 152 | D40: C - Sedan | E40: OS - On-Street | F40: PP - Perpendicular | G40: L
A41: 17 - 18 | B41: 7 | C41: 445LU01 | D41: C - Sedan | E41: OS - On-Street | F41: PA - Parallel | G41: L
B42: 7 | C42: 431AS61 | D42: T - Truck | E42: OS - On-Street | F42: PA - Parallel | G42: L
...

Sheet 8
A1: Parking Survey Sheet
A3: Date: | B3: 46176
A4: Route #: | B4: Malatia Sebastia
A5: Name/Surname: | B5: _____________
A7: Time | B7: Zone | C7: License Number | D7: Vehicle Type | E7: Location | F7: Parking Method | G7: Legal/Illegal
A8: 7=7:00 14=14:00 midnight=00:00 & etc. | B8: Zone XXX | C8: 11XX111 | D8: C - Sedan T - Truck M - Motorcycle | E8: OS - On-Street FP - Footpath SB - Setback | F8: PA - Parallel A - 45 Degree PP - Perpendicular | G8: L - Legal I - Illegal
A9: 7 - 8 | B9: 8 | C9: 78 QN 888 | D9: C - Sedan | E9: OS - On-Street | F9: A - 45 Degree | G9: L
B10: 8 | C10: 36RC763 | D10: C - Sedan | E10: OS - On-Street | F10: PA - Parallel | G10: L
A11: 8 - 9 | B11: 8 | C11: 37MZ284 | D11: C - Sedan | E11: OS - On-Street | F11: A - 45 Degree | G11: L
B12: 8 | C12: 55HH553 | D12: C - Sedan | E12: OS - On-Street | F12: A - 45 Degree | G12: L
B13: 8 | C13: 37SJ251 | D13: C - Sedan | E13: OS - On-Street | F13: PA - Parallel | G13: L
B14: 8 | C14: 49XX888 | D14: C - Sedan | E14: OS - On-Street | F14: PA - Parallel | G14: L
B15: 8 | C15: 37EW449 | D15: C - Sedan | E15: OS - On-Street | F15: PA - Parallel | G15: L
B16: 8 | C16: 37EB340 | D16: C - Sedan | E16: OS - On-Street | F16: PA - Parallel | G16: L
B17: 8 | C17: 35CD486 | D17: C - Sedan | E17: OS - On-Street | F17: PA - Parallel | G17: L
A18: 9 - 10 | B18: 8 | C18: 37KH044 | D18: C - Sedan | E18: FP - Footpath | F18: A - 45 Degree | G18: L
B19: 8 | C19: 51QQ510 | D19: C - Sedan | E19: OS - On-Street | F19: PA - Parallel | G19: L
B20: 8 | C20: 37MZ284 | D20: C - Sedan | E20: FP - Footpath | F20: PP - Perpendicular | G20: L
B21: 8 | C21: 55HH553 | D21: C - Sedan | E21: FP - Footpath | F21: PP - Perpendicular | G21: L
B22: 8 | C22: 49XX888 | D22: C - Sedan | E22: FP - Footpath | F22: PP - Perpendicular | G22: L
B23: 8 | C23: 37EW449 | D23: T - Truck | E23: FP - Footpath | F23: PP - Perpendicular | G23: L
B24: 8 | C24: 18US852 | D24: T - Truck | E24: OS - On-Street | F24: PA - Parallel | G24: L
B25: 8 | C25: 80PB080 | D25: C - Sedan | E25: OS - On-Street | F25: PA - Parallel | G25: L
B26: 8 | C26: 37EG 233 | D26: C - Sedan | E26: FP - Footpath | F26: A - 45 Degree | G26: L
B27: 8 | C27: 70LS009 | D27: C - Sedan | E27: OS - On-Street | F27: PA - Parallel | G27: L
A28: 10 - 11 | B28: 8 | C28: 70LS009 | D28: C - Sedan | E28: OS - On-Street | F28: PA - Parallel | G28: L
B29: 8 | C29: 37NT639 | D29: C - Sedan | E29: OS - On-Street | F29: PA - Parallel | G29: L
B30: 8 | C30: 33VO294 | D30: C - Sedan | E30: OS - On-Street | F30: PA - Parallel | G30: L
A31: 11 - 12 | B31: 8 | C31: 37PV453 | D31: C - Sedan | E31: OS - On-Street | F31: PA - Parallel | G31: L
B32: 8 | C32: 37EW449 | D32: T - Truck | E32: FP - Footpath | F32: PP - Perpendicular | G32: L
B33: 8 | C33: 36VU617 | D33: C - Sedan | E33: OS - On-Street | F33: A - 45 Degree | G33: L
B34: 8 | C34: 01IK019 | D34: C - Sedan | E34: FP - Footpath | F34: A - 45 Degree | G34: L
A35: 12 - 13 | B35: 8 | C35: 18LO104 | D35: C - Sedan | E35: OS - On-Street | F35: PP - Perpendicular | G35: L
B36: 8 | C36: 88RZ822 | D36: C - Sedan | E36: OS - On-Street | F36: PP - Perpendicular | G36: L
B37: 8 | C37: 01VC004 | D37: C - Sedan | E37: OS - On-Street | F37: PP - Perpendicular | G37: L
B38: 8 | C38: 37OW589 | D38: C - Sedan | E38: OS - On-Street | F38: PP - Perpendicular | G38: L
A39: 13 - 14 | B39: 8 | C39: 22MM001 | D39: C - Sedan | E39: OS - On-Street | F39: PA - Parallel | G39: L
B40: 8 | C40: 19LM009 | D40: C - Sedan | E40: OS - On-Street | F40: PA - Parallel | G40: L
B41: 8 | C41: 37HK044 | D41: C - Sedan | E41: FP - Footpath | F41: A - 45 Degree | G41: L
B42: 8 | C42: 37KD126 | D42: C - Sedan | E42: FP - Footpath | F42: A - 45 Degree | G42: L
...

Sheet 9
A1: Parking Survey Sheet
A3: Date: | B3: 46176
A4: Route #: | B4: Malatia Sebastia
A5: Name/Surname: | B5: _____________
A7: Time | B7: Zone | C7: License Number | D7: Vehicle Type | E7: Location | F7: Parking Method | G7: Legal/Illegal
A8: 7=7:00 14=14:00 midnight=00:00 & etc. | B8: Zone XXX | C8: 11XX111 | D8: C - Sedan T - Truck M - Motorcycle | E8: OS - On-Street FP - Footpath SB - Setback | F8: PA - Parallel A - 45 Degree PP - Perpendicular | G8: L - Legal I - Illegal
A9: 7 - 8 | B9: 9 | C9: 37 VA 50 | D9: C - Sedan | E9: OS - On-Street | F9: A - 45 Degree
B10: 9 | C10: 37 JX 156 | D10: C - Sedan | E10: OS - On-Street | F10: A - 45 Degree
A11: 8 - 9 | B11: 9 | C11: - | D11: - | E11: - | F11: - | G11: -
A12: 9 - 10 | B12: 9 | C12: 36UD348 | D12: C - Sedan | E12: OS - On-Street | F12: PA - Parallel
A13: 10 - 11 | B13: 9 | C13: 73BM773 | D13: C - Sedan | E13: OS - On-Street | F13: PA - Parallel
B14: 9 | C14: 55HH553 | D14: C - Sedan | E14: FP - Footpath | F14: PA - Parallel
A15: 11 - 12 | B15: 9 | C15: 30GC088 | D15: C - Sedan | E15: OS - On-Street | F15: PA - Parallel
B16: 9 | C16: 76BM766 | D16: C - Sedan | E16: FP - Footpath | F16: A - 45 Degree
B17: 9 | C17: 16DO161 | D17: C - Sedan | E17: OS - On-Street | F17: PA - Parallel
A18: 12 - 13 | B18: 9 | C18: 27KA077 | D18: C - Sedan | E18: OS - On-Street | F18: A - 45 Degree
B19: 9 | C19: 828CZ61 | D19: C - Sedan | E19: OS - On-Street | F19: PP - Perpendicular
B20: 9 | C20: 37CZ636 | D20: C - Sedan | E20: OS - On-Street | F20: PP - Perpendicular
A21: 13 - 14 | B21: 9 | C21: 20KB120 | D21: C - Sedan | E21: OS - On-Street | F21: PP - Perpendicular
B22: 9 | C22: 99LG090 | D22: C - Sedan | E22: OS - On-Street | F22: A - 45 Degree
A23: 14 - 15 | B23: 9 | C23: 20KB120 | D23: C - Sedan | E23: OS - On-Street | F23: PP - Perpendicular
B24: 9 | C24: 37CZ636 | D24: C - Sedan | E24: OS - On-Street | F24: PP - Perpendicular
B25: 9 | C25: 828CZ61 | D25: C - Sedan | E25: OS - On-Street | F25: PP - Perpendicular
A26: 15 - 16 | B26: 9 | C26: 37LB640 | D26: C - Sedan | E26: OS - On-Street | F26: PA - Parallel
B27: 9 | C27: 37HF206 | D27: C - Sedan | E27: OS - On-Street | F27: PA - Parallel
B28: 9 | C28: 36AQ750 | D28: C - Sedan | E28: OS - On-Street | F28: PA - Parallel
B29: 9 | C29: 88KK044 | D29: C - Sedan | E29: OS - On-Street | F29: PA - Parallel
A30: 16 - 17 | B30: 9 | C30: 37 KO 534 | D30: C - Sedan | E30: OS - On-Street | F30: PP - Perpendicular
B31: 9 | C31: 37 FQ 625 | D31: C - Sedan | E31: OS - On-Street | F31: PP - Perpendicular
A32: 17 - 18 | B32: 9 | C32: - | D32: - | E32: - | F32: - | G32: -
A33: 18 - 19 | B33: 9 | C33: 02SL580 | D33: C - Sedan | E33: OS - On-Street | F33: PA - Parallel
A34: 19 - 20 | B34: 9 | C34: 89ZV889 | D34: C - Sedan | E34: OS - On-Street | F34: PA - Parallel
A35: 20 - 21 | B35: 9 | C35: 89ZV889 | D35: C - Sedan | E35: OS - On-Street | F35: PA - Parallel
A36: 21 - 22 | B36: 9 | C36: 89ZV889 | D36: C - Sedan | E36: OS - On-Street | F36: PA - Parallel
A37: 22 - 23 | B37: 9 | C37: - | D37: - | E37: - | F37: - | G37: -
A38: 23 - 24 | B38: 9 | C38: - | D38: - | E38: - | F38: - | G38: -

Sheet 10
A1: Parking Survey Sheet
A3: Date: | B3: 46176
A4: Route #: | B4: Malatia Sebastia
A5: Name/Surname: | B5: _____________
A7: Time | B7: Zone | C7: License Number | D7: Vehicle Type | E7: Location | F7: Parking Method | G7: Legal/Illegal
A8: 7=7:00 14=14:00 midnight=00:00 & etc. | B8: Zone XXX | C8: 11XX111 | D8: C - Sedan T - Truck M - Motorcycle | E8: OS - On-Street FP - Footpath SB - Setback | F8: PA - Parallel A - 45 Degree PP - Perpendicular | G8: L - Legal I - Illegal
A9: 7 - 8 | B9: 10 | C9: 37 PP 439 | D9: C - Sedan | E9: OS - On-Street | F9: A - 45 Degree | G9: L
B10: 10 | C10: 34 LM 387 | D10: C - Sedan | E10: OS - On-Street | F10: A - 45 Degree | G10: L
A11: 8 - 9 | B11: 10 | C11: - | D11: -- | E11: - | F11: - | G11: -
A12: 9 - 10 | B12: 10 | C12: no number | D12: C - Sedan | E12: OS - On-Street | F12: PA - Parallel | G12: L
B13: 10 | C13: no number | D13: C - Sedan | E13: OS - On-Street | F13: PA - Parallel | G13: L
A14: 10 - 11 | B14: 10 | C14: no number | D14: C - Sedan | E14: OS - On-Street | F14: PA - Parallel | G14: L
B15: 10 | C15: no number | D15: C - Sedan | E15: OS - On-Street | F15: PA - Parallel | G15: L
A16: 11 - 12 | B16: 10 | C16: no number | D16: C - Sedan | E16: FP - Footpath | F16: PA - Parallel | G16: L
B17: 10 | C17: no number | D17: C - Sedan | E17: FP - Footpath | F17: PA - Parallel | G17: L
A18: 12 - 13 | B18: 10 | C18: 10YY200 | D18: C - Sedan | E18: OS - On-Street | F18: PP - Perpendicular | G18: L
B19: 10 | C19: 35NP236 | D19: C - Sedan | E19: FP - Footpath | F19: PP - Perpendicular | G19: L
B20: 10 | C20: 37LV829 | D20: C - Sedan | E20: OS - On-Street | F20: PP - Perpendicular | G20: L
A21: 13 - 14 | B21: 10 | C21: 99NB998 | D21: C - Sedan | E21: OS - On-Street | F21: PP - Perpendicular | G21: L
B22: 10 | C22: 36LF337 | D22: C - Sedan | E22: OS - On-Street | F22: PP - Perpendicular | G22: L
B23: 10 | C23: 01DX055 | D23: C - Sedan | E23: OS - On-Street | F23: PP - Perpendicular | G23: L
B24: 10 | C24: 37AT498 | D24: C - Sedan | E24: OS - On-Street | F24: PP - Perpendicular | G24: L
B25: 10 | C25: 71RO007 | D25: C - Sedan | E25: OS - On-Street | F25: PP - Perpendicular | G25: L
B26: 10 | C26: 37MH690 | D26: C - Sedan | E26: OS - On-Street | F26: PP - Perpendicular | G26: L
A27: 14 - 15 | B27: 10 | C27: 22MM707 | D27: C - Sedan | E27: OS - On-Street | F27: PP - Perpendicular | G27: L
B28: 10 | C28: 10XF010 | D28: C - Sedan | E28: OS - On-Street | F28: PP - Perpendicular | G28: L
B29: 10 | C29: 55GT501 | D29: C - Sedan | E29: OS - On-Street | F29: PP - Perpendicular | G29: L
B30: 10 | C30: 37MH690 | D30: C - Sedan | E30: OS - On-Street | F30: PP - Perpendicular | G30: L
B31: 10 | C31: 37AT498 | D31: C - Sedan | E31: OS - On-Street | F31: PP - Perpendicular | G31: L
B32: 10 | C32: 01DX055 | D32: C - Sedan | E32: OS - On-Street | F32: A - 45 Degree | G32: L
B33: 10 | C33: 99NB998 | D33: C - Sedan | E33: OS - On-Street | F33: A - 45 Degree | G33: L
A34: 15 - 16 | B34: 10 | C34: 11YU011 | D34: C - Sedan | E34: OS - On-Street | F34: PA - Parallel | G34: L
B35: 10 | C35: 77QX797 | D35: C - Sedan | E35: OS - On-Street | F35: PA - Parallel | G35: L
B36: 10 | C36: 21LT002 | D36: C - Sedan | E36: OS - On-Street | F36: PA - Parallel | G36: L
A37: 16 - 17 | B37: 10 | C37: 18HV008 | D37: C - Sedan | E37: OS - On-Street | F37: PA - Parallel | G37: L
B38: 10 | C38: 78 QA 778 | D38: T - Truck | E38: OS - On-Street | F38: PP - Perpendicular | G38: L
B39: 10 | C39: 05 SH 025 | D39: C - Sedan | E39: OS - On-Street | F39: PP - Perpendicular | G39: L
A40: 17 - 18 | B40: 10 | C40: 37QH697 | D40: C - Sedan | E40: OS - On-Street | F40: PA - Parallel | G40: L
B41: 10 | C41: 21BM001 | D41: C - Sedan | E41: OS - On-Street | F41: PA - Parallel | G41: L
A42: 18 - 19 | B42: 10 | C42: 36VO332 | D42: C - Sedan | E42: OS - On-Street | F42: PA - Parallel | G42: L
...

Sheet 11
A1: Parking Survey Sheet
A3: Date: | B3: 46176
A4: Route #: | B4: Malatia Sebastia
A5: Name/Surname: | B5: _____________
A7: Time | B7: Zone | C7: License Number | D7: Vehicle Type | E7: Location | F7: Parking Method | G7: Legal/Illegal
A8: 7=7:00 14=14:00 midnight=00:00 & etc. | B8: Zone XXX | C8: 11XX111 | D8: C - Sedan T - Truck M - Motorcycle | E8: OS - On-Street FP - Footpath SB - Setback | F8: PA - Parallel A - 45 Degree PP - Perpendicular | G8: L - Legal I - Illegal
A9: 7 - 8 | B9: 11 | C9: - | D9: - | E9: - | F9: - | G9: -
A10: 8 - 9 | B10: 11 | C10: 35VX988 | D10: C - Sedan | E10: OS - On-Street | F10: PA - Parallel | G10: L
A11: 9 - 10 | B11: 11 | C11: 35VX988 | D11: C - Sedan | E11: OS - On-Street | F11: PA - Parallel | G11: L
A12: 10 - 11 | B12: 11 | C12: 71FV711 | D12: C - Sedan | E12: OS - On-Street | F12: A - 45 Degree | G12: L
A13: 11 - 12 | B13: 11 | C13: 36VO040 | D13: C - Sedan | E13: FP - Footpath | F13: PA - Parallel | G13: L
A14: 12 - 13 | B14: 11 | C14: 37VM025 | D14: C - Sedan | E14: OS - On-Street | F14: A - 45 Degree | G14: L
B15: 11 | C15: 37NZ405 | D15: T - Truck | E15: OS - On-Street | F15: A - 45 Degree | G15: L
B16: 11 | C16: 55GG185 | D16: C - Sedan | E16: OS - On-Street | F16: A - 45 Degree | G16: L
B17: 11 | C17: 94XA900 | D17: T - Truck | E17: OS - On-Street | F17: A - 45 Degree | G17: L
B18: 11 | C18: 01CF011 | D18: C - Sedan | E18: OS - On-Street | F18: A - 45 Degree | G18: L
B19: 11 | C19: 88IU898 | D19: C - Sedan | E19: OS - On-Street | F19: A - 45 Degree | G19: L
A20: 13 - 14 | B20: 11 | C20: 35VX988 | D20: C - Sedan | E20: OS - On-Street | F20: PA - Parallel | G20: L
B21: 11 | C21: 37NZ405 | D21: T - Truck | E21: OS - On-Street | F21: A - 45 Degree | G21: L
A22: 14 - 15 | B22: 11 | C22: 55GG185 | D22: C - Sedan | E22: OS - On-Street | F22: A - 45 Degree | G22: L
B23: 11 | C23: 94XA900 | D23: T - Truck | E23: OS - On-Street | F23: A - 45 Degree | G23: L
B24: 11 | C24: 37VM025 | D24: C - Sedan | E24: OS - On-Street | F24: A - 45 Degree | G24: L
A25: 15 - 16 | B25: 11 | C25: 01CF011 | D25: C - Sedan | E25: OS - On-Street | F25: A - 45 Degree | G25: L
B26: 11 | C26: 36TG961 | D26: C - Sedan | E26: FP - Footpath | F26: PA - Parallel | G26: L
A27: 16 - 17 | B27: 11 | C27: 08OV090 | D27: C - Sedan | E27: OS - On-Street | F27: PA - Parallel | G27: L
B28: 11 | C28: 37NH359 | D28: C - Sedan | E28: OS - On-Street | F28: PA - Parallel | G28: L
B29: 11 | C29: 36QU109 | D29: C - Sedan | E29: OS - On-Street | F29: PA - Parallel | G29: L
A30: 17 - 18 | B30: 11 | C30: 81 EE 333 | D30: C - Sedan | E30: OS - On-Street | F30: PP - Perpendicular | G30: L
B31: 11 | C31: 67 UU 007 | D31: C - Sedan | E31: OS - On-Street | F31: PP - Perpendicular | G31: L
A32: 18 - 19 | B32: 11 | C32: 35VX988 | D32: C - Sedan | E32: OS - On-Street | F32: PA - Parallel | G32: L
B33: 11 | C33: 96 SG 006* | D33: T - Truck | E33: OS - On-Street | F33: PP - Perpendicular | G33: L
A34: 19 - 20 | B34: 11 | C34: 35VX988 | D34: C - Sedan | E34: OS - On-Street | F34: PA - Parallel | G34: L
A35: 20 - 21 | B35: 11 | C35: 34CC433 | D35: C - Sedan | E35: OS - On-Street | F35: PA - Parallel | G35: L
B36: 11 | C36: 35VX988 | D36: C - Sedan | E36: OS - On-Street | F36: PA - Parallel | G36: L
B37: 11 | C37: 37EV660 | D37: C - Sedan | E37: OS - On-Street | F37: PA - Parallel | G37: L
A38: 21 - 22 | B38: 11 | C38: 35VX988 | D38: C - Sedan | E38: OS - On-Street | F38: PA - Parallel | G38: L
A39: 22 - 23 | B39: 11 | C39: 37EV660 | D39: C - Sedan | E39: OS - On-Street | F39: PA - Parallel | G39: L
A40: 23 - 24 | B40: 11 | C40: 21BM001 | D40: C - Sedan | E40: FP - Footpath | F40: PA - Parallel | G40: L
B41: 11 | C41: 92AR922 | D41: C - Sedan | E41: FP - Footpath | F41: PA - Parallel | G41: L

Sheet 12
A1: Parking Survey Sheet
A3: Date: | B3: 46176
A4: Route #: | B4: Malatia Sebastia
A5: Name/Surname: | B5: _____________
A7: Time | B7: Zone | C7: License Number | D7: Vehicle Type | E7: Location | F7: Parking Method | G7: Legal/Illegal
A8: 7=7:00 14=14:00 midnight=00:00 & etc. | B8: Zone XXX | C8: 11XX111 | D8: C - Sedan T - Truck M - Motorcycle | E8: OS - On-Street FP - Footpath SB - Setback | F8: PA - Parallel A - 45 Degree PP - Perpendicular | G8: L - Legal I - Illegal
A9: 7 - 8 | B9: 12 | C9: 35 VC 218 | D9: C - Sedan | E9: OS - On-Street | F9: A - 45 Degree | G9: L
B10: 12 | C10: 96 ES 006* | D10: T - Truck | E10: OS - On-Street | F10: PP - Perpendicular | G10: L
A11: 8 - 9 | B11: 12 | C11: 61WM600 | D11: C - Sedan | E11: OS - On-Street | F11: PA - Parallel | G11: L
B12: 12 | C12: 37OJ753 | D12: C - Sedan | E12: OS - On-Street | F12: PA - Parallel | G12: L
B13: 12 | C13: 37TJ246 | D13: C - Sedan | E13: OS - On-Street | F13: PA - Parallel | G13: L
B14: 12 | C14: 37VD280 | D14: T - Truck | E14: OS - On-Street | F14: PA - Parallel | G14: L
B15: 12 | C15: 33LT221 | D15: T - Truck | E15: OS - On-Street | F15: PA - Parallel | G15: L
A16: 9 - 10 | B16: 12 | C16: 96JI996 | D16: C - Sedan | E16: OS - On-Street | F16: PA - Parallel | G16: L
B17: 12 | C17: 90TD500 | D17: C - Sedan | E17: SB - Setback | F17: PA - Parallel | G17: L
B18: 12 | C18: 61WM600 | D18: C - Sedan | E18: OS - On-Street | F18: PA - Parallel | G18: L
B19: 12 | C19: 37PI446 | D19: C - Sedan | E19: OS - On-Street | F19: PA - Parallel | G19: L
B20: 12 | C20: 37RD374 | D20: T - Truck | E20: SB - Setback | F20: PA - Parallel | G20: L
B21: 12 | C21: 37LB163 | D21: C - Sedan | E21: SB - Setback | F21: PA - Parallel | G21: L
B22: 12 | C22: 21BM001 | D22: C - Sedan | E22: OS - On-Street | F22: PA - Parallel | G22: L
B23: 12 | C23: 01TO800 | D23: C - Sedan | E23: OS - On-Street | F23: PA - Parallel | G23: L
B24: 12 | C24: 3712FI | D24: C - Sedan | E24: OS - On-Street | F24: PA - Parallel | G24: L
B25: 12 | C25: no number | D25: C - Sedan | E25: OS - On-Street | F25: PA - Parallel | G25: L
B26: 12 | C26: no number | D26: C - Sedan | E26: OS - On-Street | F26: PA - Parallel | G26: L
B27: 12 | C27: 1931FE | D27: C - Sedan | E27: OS - On-Street | F27: PA - Parallel | G27: L
A28: 10 - 11 | B28: 12 | C28: 10II051 | D28: C - Sedan | E28: OS - On-Street | F28: PA - Parallel | G28: L
B29: 12 | C29: 999ZZ86 | D29: C - Sedan | E29: OS - On-Street | F29: PA - Parallel | G29: L
B30: 12 | C30: 37OQ637 | D30: C - Sedan | E30: OS - On-Street | F30: PA - Parallel | G30: L
B31: 12 | C31: 70EN707 | D31: C - Sedan | E31: OS - On-Street | F31: PA - Parallel | G31: L
B32: 12 | C32: 37JX170 | D32: C - Sedan | E32: OS - On-Street | F32: PA - Parallel | G32: L
A33: 11 - 12 | B33: 12 | C33: 37PI446 | D33: C - Sedan | E33: FP - Footpath | F33: PA - Parallel | G33: L
B34: 12 | C34: 37RD374 | D34: T - Truck | E34: FP - Footpath | F34: PA - Parallel | G34: L
B35: 12 | C35: 35OR151 | D35: C - Sedan | E35: FP - Footpath | F35: PA - Parallel | G35: L
B36: 12 | C36: 37LP163 | D36: C - Sedan | E36: FP - Footpath | F36: PA - Parallel | G36: L
B37: 12 | C37: 21BM001 | D37: C - Sedan | E37: FP - Footpath | F37: PA - Parallel | G37: L
A38: 12 - 13 | B38: 12 | C38: 37HI033 | D38: C - Sedan | E38: OS - On-Street | F38: PA - Parallel | G38: L
B39: 12 | C39: 16LL001 | D39: C - Sedan | E39: OS - On-Street | F39: PA - Parallel | G39: L
B40: 12 | C40: 71VS071 | D40: C - Sedan | E40: OS - On-Street | F40: PA - Parallel | G40: L
A41: 13 - 14 | B41: 12 | C41: 37DN291 | D41: C - Sedan | E41: OS - On-Street | F41: A - 45 Degree | G41: L
B42: 12 | C42: 37NP540 | D42: C - Sedan | E42: OS - On-Street | F42: A - 45 Degree | G42: L
...

Sheet 13
A1: Parking Survey Sheet
A3: Date: | B3: 46176
A4: Route #: | B4: Malatia Sebastia
A5: Name/Surname: | B5: _____________
A7: Time | B7: Zone | C7: License Number | D7: Vehicle Type | E7: Location | F7: Parking Method | G7: Legal/Illegal
A8: 7=7:00 14=14:00 midnight=00:00 & etc. | B8: Zone XXX | C8: 11XX111 | D8: C - Sedan T - Truck M - Motorcycle | E8: OS - On-Street FP - Footpath SB - Setback | F8: PA - Parallel A - 45 Degree PP - Perpendicular | G8: L - Legal I - Illegal
A9: 7 - 9 | B9: 13 | C9: 66 OV 060 | D9: C - Sedan | E9: OS - On-Street | F9: A - 45 Degree | G9: L
A10: 8 - 9 | B10: - | C10: - | D10: - | E10: - | F10: - | G10: -
A11: 9 - 10 | B11: 13 | C11: 37CB659 | D11: C - Sedan | E11: OS - On-Street | F11: PA - Parallel | G11: L
B12: 13 | C12: 689AX61 | D12: T - Truck | E12: OS - On-Street | F12: PA - Parallel | G12: L
B13: 13 | C13: 37TV368 | D13: C - Sedan | E13: OS - On-Street | F13: PA - Parallel | G13: L
B14: 13 | C14: 11QO010 | D14: C - Sedan | E14: OS - On-Street | F14: PA - Parallel | G14: L
A15: 10 - 11 | B15: 13 | C15: - | D15: - | E15: - | F15: - | G15: -
A16: 11 - 12 | B16: 13 | C16: 36SF765 | D16: C - Sedan | E16: FP - Footpath | F16: PA - Parallel | G16: L
B17: 13 | C17: 89ZV889 | D17: C - Sedan | E17: FP - Footpath | F17: PA - Parallel | G17: L
B18: 13 | C18: 03II014 | D18: C - Sedan | E18: FP - Footpath | F18: PA - Parallel | G18: L
A19: 12 - 13 | B19: 13 | C19: 71OQ011 | D19: C - Sedan | E19: OS - On-Street | F19: PP - Perpendicular | G19: L
B20: 13 | C20: 70OG072 | D20: C - Sedan | E20: OS - On-Street | F20: PP - Perpendicular | G20: L
B21: 13 | C21: 89ZV889 | D21: C - Sedan | E21: OS - On-Street | F21: PP - Perpendicular | G21: L
A22: 13 - 14 | B22: 13 | C22: 37OJ364 | D22: C - Sedan | E22: OS - On-Street | F22: PA - Parallel | G22: L
B23: 13 | C23: 18HV008 | D23: C - Sedan | E23: OS - On-Street | F23: PA - Parallel | G23: L
B24: 13 | C24: 37TK001 | D24: C - Sedan | E24: OS - On-Street | F24: PA - Parallel | G24: L
A25: 14 - 15 | B25: 13 | C25: 37OX258 | D25: C - Sedan | E25: OS - On-Street | F25: A - 45 Degree | G25: L
B26: 13 | C26: 32WD322 | D26: C - Sedan | E26: OS - On-Street | F26: A - 45 Degree | G26: L
A27: 15 - 16 | B27: 13 | C27: 37AA079 | D27: C - Sedan | E27: OS - On-Street | F27: PA - Parallel | G27: L
B28: 13 | C28: 37GE747 | D28: C - Sedan | E28: OS - On-Street | F28: PA - Parallel | G28: L
B29: 13 | C29: 89ZB889 | D29: C - Sedan | E29: OS - On-Street | F29: PA - Parallel | G29: L
B30: 13 | C30: 37CB659 | D30: C - Sedan | E30: OS - On-Street | F30: PA - Parallel | G30: L
A31: 16 - 17 | B31: 13 | C31: 37XK926 | D31: C - Sedan | E31: OS - On-Street | F31: PA - Parallel | G31: L
B32: 13 | C32: 37HW043 | D32: C - Sedan | E32: OS - On-Street | F32: PP - Perpendicular | G32: L
B33: 13 | C33: 37JA852 | D33: C - Sedan | E33: OS - On-Street | F33: PA - Parallel | G33: L
B34: 13 | C34: 50 PP 015 | D34: C - Sedan | E34: OS - On-Street | F34: PP - Perpendicular | G34: L
B35: 13 | C35: 07 MN 001 | D35: C - Sedan | E35: OS - On-Street | F35: PP - Perpendicular | G35: L
A36: 17 - 18 | B36: 13 | C36: 21SO341 | D36: C - Sedan | E36: OS - On-Street | F36: PA - Parallel | G36: L
B37: 13 | C37: 77AW797 | D37: C - Sedan | E37: OS - On-Street | F37: PA - Parallel | G37: L
B38: 13 | C38: 32OS574 | D38: C - Sedan | E38: OS - On-Street | F38: PA - Parallel | G38: L
B39: 13 | C39: 36UD348 | D39: C - Sedan | E39: OS - On-Street | F39: PA - Parallel | G39: L
B40: 13 | C40: 81UK881 | D40: C - Sedan | E40: OS - On-Street | F40: PA - Parallel | G40: L
A41: 18 - 19 | B41: 13 | C41: 77AW797 | D41: C - Sedan | E41: OS - On-Street | F41: PA - Parallel | G41: L
B42: 13 | C42: 21SO351 | D42: C - Sedan | E42: OS - On-Street | F42: PA - Parallel | G42: L
...

Sheet 14
A1: Parking Survey Sheet
A3: Date: | B3: 46176
A4: Route #: | B4: Malatia Sebastia
A5: Name/Surname: | B5: _____________
A7: Time | B7: Zone | C7: License Number | D7: Vehicle Type | E7: Location | F7: Parking Method | G7: Legal/Illegal
A8: 7=7:00 14=14:00 midnight=00:00 & etc. | B8: Zone XXX | C8: 11XX111 | D8: C - Sedan T - Truck M - Motorcycle | E8: OS - On-Street FP - Footpath SB - Setback | F8: PA - Parallel A - 45 Degree PP - Perpendicular | G8: L - Legal I - Illegal
A9: 7 - 8 | B9: 14 | C9: 65OQ065 | D9: C - Sedan | E9: SB - Setback | F9: PA - Parallel | G9: L
B10: 14 | C10: 66DD888 | D10: C - Sedan | E10: SB - Setback | F10: PA - Parallel | G10: L
B11: 14 | C11: 35HH728 | D11: C - Sedan | E11: SB - Setback | F11: PA - Parallel | G11: L
B12: 14 | C12: 27KK777 | D12: C - Sedan | E12: SB - Setback | F12: PA - Parallel | G12: L
B13: 14 | C13: 10OW101 | D13: C - Sedan | E13: SB - Setback | F13: PA - Parallel | G13: L
B14: 14 | C14: 26UI283 | D14: C - Sedan | E14: SB - Setback | F14: PA - Parallel | G14: L
B15: 14 | C15: 18Hs188 | D15: C - Sedan | E15: SB - Setback | F15: PA - Parallel | G15: L
B16: 14 | C16: 282UO88 | D16: T - Truck | E16: SB - Setback | F16: PA - Parallel | G16: L
B17: 14 | C17: 99ka999 | D17: C - Sedan | E17: SB - Setback | F17: PA - Parallel | G17: L
B18: 14 | C18: 27TU267 | D18: C - Sedan | E18: SB - Setback | F18: PA - Parallel | G18: L
B19: 14 | C19: 91FY727 | D19: C - Sedan | E19: SB - Setback | F19: PA - Parallel | G19: L
B20: 14 | C20: PI-222-PI | D20: C - Sedan | E20: SB - Setback | F20: PA - Parallel | G20: L
B21: 14 | C21: 78YY788 | D21: C - Sedan | E21: SB - Setback | F21: PA - Parallel | G21: L
A22: 8 - 9 | B22: 14 | C22: 34ZN239 | D22: C - Sedan | E22: SB - Setback | F22: PA - Parallel | G22: L
B23: 14 | C23: no number | D23: C - Sedan | E23: SB - Setback | F23: PA - Parallel | G23: L
B24: 14 | C24: 37EM653 | D24: C - Sedan | E24: SB - Setback | F24: PA - Parallel | G24: L
B25: 14 | C25: 37KR824 | D25: C - Sedan | E25: SB - Setback | F25: PA - Parallel | G25: L
A26: 9 - 10 | B26: 14 | C26: 34ZN239 | D26: C - Sedan | E26: SB - Setback | F26: PA - Parallel | G26: L
B27: 14 | C27: 37EM653 | D27: C - Sedan | E27: SB - Setback | F27: PA - Parallel | G27: L
B28: 14 | C28: 37KR824 | D28: C - Sedan | E28: SB - Setback | F28: PA - Parallel | G28: L
B29: 14 | C29: 37VO782 | D29: C - Sedan | E29: SB - Setback | F29: PA - Parallel | G29: L
B30: 14 | C30: 01VH770 | D30: C - Sedan | E30: SB - Setback | F30: PA - Parallel | G30: L
B31: 14 | C31: 37GN336 | D31: C - Sedan | E31: SB - Setback | F31: PA - Parallel | G31: L
A32: 10 - 11 | B32: 14 | C32: 37VO782 | D32: C - Sedan | E32: SB - Setback | F32: PA - Parallel | G32: L
B33: 14 | C33: no number | D33: C - Sedan | E33: SB - Setback | F33: PA - Parallel | G33: L
B34: 14 | C34: 01VH770 | D34: C - Sedan | E34: SB - Setback | F34: PA - Parallel | G34: L
B35: 14 | C35: 37GN336 | D35: C - Sedan | E35: SB - Setback | F35: PA - Parallel | G35: L
B36: 14 | C36: 37KR824 | D36: C - Sedan | E36: SB - Setback | F36: PA - Parallel | G36: L
B37: 14 | C37: 10RY777 | D37: C - Sedan | E37: SB - Setback | F37: PA - Parallel | G37: L
B38: 14 | C38: 72GO772 | D38: C - Sedan | E38: SB - Setback | F38: PA - Parallel | G38: L
B39: 14 | C39: 77IZ767 | D39: C - Sedan | E39: SB - Setback | F39: PA - Parallel | G39: L
B40: 14 | C40: 51TM001 | D40: C - Sedan | E40: SB - Setback | F40: PA - Parallel | G40: L
B41: 14 | C41: 78XX001 | D41: C - Sedan | E41: SB - Setback | F41: PA - Parallel | G41: L
B42: 14 | C42: 37KR824 | D42: C - Sedan | E42: SB - Setback | F42: PP - Perpendicular | G42: L
...

Sheet 15
A1: Parking Survey Sheet
A3: Date: | B3: 46176
A4: Route #: | B4: Malatia Sebastia
A5: Name/Surname: | B5: _____________
A7: Time | B7: Zone | C7: License Number | D7: Vehicle Type | E7: Location | F7: Parking Method | G7: Legal/Illegal
A8: 7=7:00 14=14:00 midnight=00:00 & etc. | B8: Zone XXX | C8: 11XX111 | D8: C - Sedan T - Truck M - Motorcycle | E8: OS - On-Street FP - Footpath SB - Setback | F8: PA - Parallel A - 45 Degree PP - Perpendicular | G8: L - Legal I - Illegal
A9: 7 - 8 | B9: 15 | C9: 15DT178 | D9: C - Sedan | E9: OS - On-Street | F9: PA - Parallel | G9: L
B10: 15 | C10: 27JJ819 | D10: C - Sedan | E10: OS - On-Street | F10: PA - Parallel | G10: L
B11: 15 | C11: 888IO82 | D11: C - Sedan | E11: OS - On-Street | F11: PA - Parallel | G11: L
B12: 15 | C12: 35KT418 | D12: C - Sedan | E12: OS - On-Street | F12: PA - Parallel | G12: L
B13: 15 | C13: 77TT777 | D13: C - Sedan | E13: OS - On-Street | F13: PA - Parallel | G13: L
B14: 15 | C14: 14BM263 | D14: C - Sedan | E14: OS - On-Street | F14: PA - Parallel | G14: L
B15: 15 | C15: 09XP741 | D15: C - Sedan | E15: OS - On-Street | F15: PA - Parallel | G15: L
B16: 15 | C16: 67VK390 | D16: C - Sedan | E16: OS - On-Street | F16: PA - Parallel | G16: L
A17: 8 - 9 | B17: 15 | C17: 04AO044 | D17: C - Sedan | E17: FP - Footpath | F17: PA - Parallel | G17: L
B18: 15 | C18: 37MR278 | D18: C - Sedan | E18: FP - Footpath | F18: PA - Parallel | G18: L
B19: 15 | C19: 35TO056 | D19: C - Sedan | E19: FP - Footpath | F19: PA - Parallel | G19: L
B20: 15 | C20: 37UG188 | D20: C - Sedan | E20: FP - Footpath | F20: PA - Parallel | G20: L
B21: 15 | C21: 60ZZ601 | D21: C - Sedan | E21: FP - Footpath | F21: PA - Parallel | G21: L
B22: 15 | C22: 77WI772 | D22: C - Sedan | E22: FP - Footpath | F22: PA - Parallel | G22: L
B23: 15 | C23: 05PP606 | D23: C - Sedan | E23: FP - Footpath | F23: PA - Parallel | G23: L
B24: 15 | C24: 34PZ691 | D24: T - Truck | E24: FP - Footpath | F24: PA - Parallel | G24: L
B25: 15 | C25: 37BV064 | D25: T - Truck | E25: FP - Footpath | F25: PA - Parallel | G25: L
B26: 15 | C26: 08PO808 | D26: C - Sedan | E26: FP - Footpath | F26: PA - Parallel | G26: L
B27: 15 | C27: 89XO089 | D27: C - Sedan | E27: FP - Footpath | F27: A - 45 Degree | G27: L
B28: 15 | C28: 77VX977 | D28: C - Sedan | E28: FP - Footpath | F28: A - 45 Degree | G28: L
B29: 15 | C29: 97RP001 | D29: T - Truck | E29: FP - Footpath | F29: A - 45 Degree | G29: L
... B35: 15 | C35: 57QO077 | D35: C - Sedan | E35: FP - Footpath | F35: PA - Parallel | G35: L
A36: 9 - 10 | B36: 15 | C36: 50SN078 | D36: C - Sedan | E36: OS - On-Street | F36: PA - Parallel | G36: L
B37: 15 | C37: 36FR866 | D37: C - Sedan | E37: OS - On-Street | F37: PA - Parallel | G37: L
B38: 15 | C38: 37KS142 | D38: C - Sedan | E38: OS - On-Street | F38: PA - Parallel | G38: L
B39: 15 | C39: 36DQ002 | D39: T - Truck | E39: OS - On-Street | F39: PA - Parallel | G39: L
B40: 15 | C40: 37KW952 | D40: C - Sedan | E40: OS - On-Street | F40: PA - Parallel | G40: L
B41: 15 | C41: 35NL600 | D41: C - Sedan | E41: OS - On-Street | F41: PA - Parallel | G41: L
B42: 15 | C42: 35TO056 | D42: T - Truck | E42: OS - On-Street | F42: PA - Parallel | G42: L
B43: 15 | C43: 37LN496 | D43: C - Sedan | E43: OS - On-Street | F43: A - 45 Degree | G43: L
B44: 15 | C44: 92KK888 | D44: C - Sedan | E44: OS - On-Street | F44: A - 45 Degree | G44: L
B45: 15 | C45: 37UA518 | D45: T - Truck | E45: OS - On-Street | F45: A - 45 Degree | G45: L
B46: 15 | C46: 37VK646 | D46: C - Sedan | E46: OS - On-Street | F46: PA - Parallel | G46: L
B47: 15 | C47: 60ZZ601 | D47: C - Sedan | E47: OS - On-Street | F47: A - 45 Degree | G47: L
...

Sheet 16
A1: Parking Survey Sheet
A3: Date: | B3: 46176
A4: Route #: | B4: Malatia Sebastia
A5: Name/Surname: | B5: _____________
A7: Time | B7: Zone | C7: License Number | D7: Vehicle Type | E7: Location | F7: Parking Method | G7: Legal/Illegal
A8: 7=7:00 14=14:00 midnight=00:00 & etc. | B8: Zone XXX | C8: 11XX111 | D8: C - Sedan T - Truck M - Motorcycle | E8: OS - On-Street FP - Footpath SB - Setback | F8: PA - Parallel A - 45 Degree PP - Perpendicular | G8: L - Legal I - Illegal
A9: 7 - 8 | B9: 16 | C9: 31HC574 | D9: C - Sedan | E9: OS - On-Street | F9: PA - Parallel | G9: L
B10: 16 | C10: 05TT050 | D10: C - Sedan | E10: OS - On-Street | F10: PA - Parallel | G10: L
B11: 16 | C11: 73KM821 | D11: C - Sedan | E11: OS - On-Street | F11: PA - Parallel | G11: L
B12: 16 | C12: 42PV306 | D12: C - Sedan | E12: OS - On-Street | F12: PA - Parallel | G12: L
B13: 16 | C13: 18BK647 | D13: C - Sedan | E13: OS - On-Street | F13: PA - Parallel | G13: L
B14: 16 | C14: 07MM700 | D14: C - Sedan | E14: OS - On-Street | F14: PA - Parallel | G14: L
B15: 16 | C15: 64TN283 | D15: C - Sedan | E15: OS - On-Street | F15: PA - Parallel | G15: L
B16: 16 | C16: 44EE444 | D16: C - Sedan | E16: OS - On-Street | F16: PA - Parallel | G16: L
B17: 16 | C17: 29XO158 | D17: C - Sedan | E17: OS - On-Street | F17: PA - Parallel | G17: L
B18: 16 | C18: 81KP935 | D18: C - Sedan | E18: OS - On-Street | F18: PA - Parallel | G18: L
A19: 8 - 9 | B19: 16 | C19: 34OV740 | D19: C - Sedan | E19: FP - Footpath | F19: PA - Parallel | G19: L
B20: 16 | C20: 22PP262 | D20: C - Sedan | E20: FP - Footpath | F20: PA - Parallel | G20: L
B21: 16 | C21: 28AA100 | D21: T - Truck | E21: FP - Footpath | F21: PA - Parallel | G21: L
B22: 16 | C22: 36AD702 | D22: C - Sedan | E22: FP - Footpath | F22: PA - Parallel | G22: L
B23: 16 | C23: 09WO909 | D23: C - Sedan | E23: FP - Footpath | F23: PA - Parallel | G23: L
B24: 16 | C24: 37TJ928 | D24: C - Sedan | E24: FP - Footpath | F24: PA - Parallel | G24: L
A25: 9 - 10 | B25: 16 | C25: 37PB114 | D25: C - Sedan | E25: FP - Footpath | F25: PA - Parallel | G25: L
B26: 16 | C26: 34OV740 | D26: C - Sedan | E26: FP - Footpath | F26: PA - Parallel | G26: L
B27: 16 | C27: 50HD101 | D27: C - Sedan | E27: OS - On-Street | F27: PA - Parallel | G27: L
B28: 16 | C28: 50CD550 | D28: C - Sedan | E28: OS - On-Street | F28: A - 45 Degree | G28: L
B29: 16 | C29: 35RR273 | D29: C - Sedan | E29: OS - On-Street | F29: PA - Parallel | G29: L
B30: 16 | C30: 22PP262 | D30: C - Sedan | E30: OS - On-Street | F30: PA - Parallel | G30: L
B31: 16 | C31: 21ZF221 | D31: C - Sedan | E31: OS - On-Street | F31: A - 45 Degree | G31: L
B32: 16 | C32: 54AA445 | D32: C - Sedan | E32: OS - On-Street | F32: PA - Parallel | G32: L
B33: 16 | C33: 36OT098 | D33: C - Sedan | E33: OS - On-Street | F33: PA - Parallel | G33: L
B34: 16 | C34: 28OO100 | D34: C - Sedan | E34: OS - On-Street | F34: PA - Parallel | G34: L
B35: 16 | C35: 28AA100 | D35: T - Truck | E35: OS - On-Street | F35: PA - Parallel | G35: L
B36: 16 | C36: 37QS766 | D36: C - Sedan | E36: OS - On-Street | F36: PA - Parallel | G36: L
B37: 16 | C37: 09KO909 | D37: C - Sedan | E37: OS - On-Street | F37: PA - Parallel | G37: L
B38: 16 | C38: 85UA085 | D38: C - Sedan | E38: OS - On-Street | F38: PA - Parallel | G38: L
A39: 10 - 11 | B39: 16 | C39: 50HD101 | D39: C - Sedan | E39: OS - On-Street | F39: A - 45 Degree | G39: L
B40: 16 | C40: 50CD550 | D40: C - Sedan | E40: OS - On-Street | F40: A - 45 Degree | G40: L
B41: 16 | C41: 01RT101 | D41: C - Sedan | E41: OS - On-Street | F41: A - 45 Degree | G41: L
B42: 16 | C42: 37JA852 | D42: C - Sedan | E42: OS - On-Street | F42: PA - Parallel | G42: L
...

Sheet 17
A1: Parking Survey Sheet
A3: Date: | B3: 46176
A4: Route #: | B4: Malatia Sebastia
A5: Name/Surname: | B5: _____________
A7: Time | B7: Zone | C7: License Number | D7: Vehicle Type | E7: Location | F7: Parking Method | G7: Legal/Illegal
A8: 7=7:00 14=14:00 midnight=00:00 & etc. | B8: Zone XXX | C8: 11XX111 | D8: C - Sedan T - Truck M - Motorcycle | E8: OS - On-Street FP - Footpath SB - Setback | F8: PA - Parallel A - 45 Degree PP - Perpendicular | G8: L - Legal I - Illegal
A9: 7 - 8 | B9: 17 | C9: 37PB439 | D9: C - Sedan | E9: SB - Setback | F9: A - 45 Degree | G9: L
B10: 17 | C10: 06AK061 | D10: C - Sedan | E10: SB - Setback | F10: A - 45 Degree | G10: L
B11: 17 | C11: 37VA502 | D11: C - Sedan | E11: SB - Setback | F11: PA - Parallel | G11: L
B12: 17 | C12: 78QA778 | D12: T - Truck | E12: SB - Setback | F12: PA - Parallel | G12: L
B13: 17 | C13: 77KK997 | D13: C - Sedan | E13: SB - Setback | F13: PA - Parallel | G13: L
B14: 17 | C14: 21JJ210 | D14: C - Sedan | E14: SB - Setback | F14: PA - Parallel | G14: L
B15: 17 | C15: 025AS61 | D15: T - Truck | E15: SB - Setback | F15: PA - Parallel | G15: L
B16: 17 | C16: 19NL009 | D16: C - Sedan | E16: SB - Setback | F16: PA - Parallel | G16: L
B17: 17 | C17: 07RM070 | D17: T - Truck | E17: SB - Setback | F17: PA - Parallel | G17: L
B18: 17 | C18: 35VY035 | D18: C - Sedan | E18: SB - Setback | F18: A - 45 Degree | G18: L
A19: 8 - 9 | B19: 17 | C19: 71OO171 | D19: C - Sedan | E19: OS - On-Street | F19: PA - Parallel | G19: L
B20: 17 | C20: 46BK251 | D20: C - Sedan | E20: OS - On-Street | F20: PA - Parallel | G20: L
B21: 17 | C21: 33CC333 | D21: C - Sedan | E21: OS - On-Street | F21: PA - Parallel | G21: L
B22: 17 | C22: 08TM694 | D22: C - Sedan | E22: OS - On-Street | F22: PA - Parallel | G22: L
B23: 17 | C23: 97VV123 | D23: C - Sedan | E23: OS - On-Street | F23: PA - Parallel | G23: L
B24: 17 | C24: 21OO012 | D24: C - Sedan | E24: OS - On-Street | F24: PA - Parallel | G24: L
B25: 17 | C25: 54HK786 | D25: C - Sedan | E25: OS - On-Street | F25: PA - Parallel | G25: L
B26: 17 | C26: 12AB340 | D26: C - Sedan | E26: OS - On-Street | F26: PA - Parallel | G26: L
B27: 17 | C27: 79OO997 | D27: C - Sedan | E27: OS - On-Street | F27: PA - Parallel | G27: L
A28: 9 - 10 | B28: 17 | C28: 37HK089 | D28: C - Sedan | E28: FP - Footpath | F28: PA - Parallel | G28: L
B29: 17 | C29: 81ON808 | D29: C - Sedan | E29: FP - Footpath | F29: PA - Parallel | G29: L
B30: 17 | C30: 71XY707 | D30: C - Sedan | E30: FP - Footpath | F30: PA - Parallel | G30: L
B31: 17 | C31: 37NI795 | D31: C - Sedan | E31: FP - Footpath | F31: PA - Parallel | G31: L
B32: 17 | C32: 36VN716 | D32: C - Sedan | E32: OS - On-Street | F32: A - 45 Degree | G32: L
B33: 17 | C33: 35OG265 | D33: C - Sedan | E33: OS - On-Street | F33: PP - Perpendicular | G33: L
B34: 17 | C34: 88UC888 | D34: C - Sedan | E34: OS - On-Street | F34: A - 45 Degree | G34: L
B35: 17 | C35: 02EL001 | D35: C - Sedan | E35: OS - On-Street | F35: A - 45 Degree | G35: L
B36: 17 | C36: 66IQ966 | D36: C - Sedan | E36: OS - On-Street | F36: A - 45 Degree | G36: L
B37: 17 | C37: 003ZO01 | D37: C - Sedan | E37: OS - On-Street | F37: PP - Perpendicular | G37: L
B38: 17 | C38: 37WM987 | D38: C - Sedan | E38: OS - On-Street | F38: A - 45 Degree | G38: L
B39: 17 | C39: 37JB987 | D39: C - Sedan | E39: OS - On-Street | F39: PP - Perpendicular | G39: L
B40: 17 | C40: 66MW666 | D40: C - Sedan | E40: OS - On-Street | F40: A - 45 Degree | G40: L
... B42: 17 | C42: 15XC155 | D42: C - Sedan | E42: OS - On-Street | F42: PP - Perpendicular | G42: L
A43: 10 - 11 | B43: 17 | C43: 01ZI007 | D43: C - Sedan | E43: OS - On-Street | F43: PP - Perpendicular | G43: L
...

Sheet 18
A1: Parking Survey Sheet
A3: Date: | B3: 46176
A4: Route #: | B4: Malatia Sebastia
A5: Name/Surname: | B5: _____________
A7: Time | B7: Zone | C7: License Number | D7: Vehicle Type | E7: Location | F7: Parking Method | G7: Legal/Illegal
A8: 7=7:00 14=14:00 midnight=00:00 & etc. | B8: Zone XXX | C8: 11XX111 | D8: C - Sedan T - Truck M - Motorcycle | E8: OS - On-Street FP - Footpath SB - Setback | F8: PA - Parallel A - 45 Degree PP - Perpendicular | G8: L - Legal I - Illegal
A9: 7 - 8 | B9: 18 | C9: 98DA008 | D9: C - Sedan | E9: SB - Setback | F9: PA - Parallel | G9: L
B10: 18 | C10: 36TO645 | D10: C - Sedan | E10: SB - Setback | F10: PP - Perpendicular | G10: L
B11: 18 | C11: 51TA551 | D11: C - Sedan | E11: SB - Setback | F11: PP - Perpendicular | G11: L
B12: 18 | C12: 37MZ284 | D12: C - Sedan | E12: SB - Setback | F12: PP - Perpendicular | G12: L
