Workbook

Sheet 59
A1: Parking Survey Sheet
A3: Date: | B3: 46175
A4: Route #: | B4: Mega Mall
A5: Name/Surname: | B5: _____________
A7: Time | B7: Zone | C7: License Number | D7: Vehicle Type | E7: Location | F7: Parking Method | G7: Legal/Illegal
A8: 7=7:00 14=14:00 midnight=00:00 & etc. | B8: Zone XXX | C8: 11XX111 | D8: C - Sedan T - Truck M - Motorcycle | E8: OS - On-Street FP - Footpath SB - Setback | F8: PA - Parallel A - 45 Degree PP - Perpendicular | G8: L - Legal I - Illegal
A9: 7 - 8 | B9: - | C9: - | D9: - | E9: - | F9: - | G9: -
A10: 8 - 9 | B10: - | C10: - | D10: - | E10: - | F10: - | G10: -
A11: 9 - 10 | B11: - | C11: - | D11: - | E11: - | F11: - | G11: -
A12: 10 - 11 | B12: - | C12: - | D12: - | E12: - | F12: - | G12: -
A13: 11 - 12 | B13: - | C13: - | D13: - | E13: - | F13: - | G13: -
A14: 12 - 13 | B14: - | C14: - | D14: - | E14: - | F14: - | G14: -
A15: 13 - 14 | B15: - | C15: - | D15: - | E15: - | F15: - | G15: -
A16: 14 - 15 | B16: - | C16: - | D16: - | E16: - | F16: - | G16: -
A17: 15 - 16 | B17: - | C17: - | D17: - | E17: - | F17: - | G17: -
A18: 16 - 17 | B18: - | C18: - | D18: - | E18: - | F18: - | G18: -
... A25: 23 - 24 | B25: - | C25: - | D25: - | E25: - | F25: - | G25: -

Sheet 60
A1: Parking Survey Sheet
A3: Date: | B3: 46175
A4: Route #: | B4: Mega Mall
A5: Name/Surname: | B5: _____________
A7: Time | B7: Zone | C7: License Number | D7: Vehicle Type | E7: Location | F7: Parking Method | G7: Legal/Illegal
A8: 7=7:00 14=14:00 midnight=00:00 & etc. | B8: Zone XXX | C8: 11XX111 | D8: C - Sedan T - Truck M - Motorcycle | E8: OS - On-Street FP - Footpath SB - Setback | F8: PA - Parallel A - 45 Degree PP - Perpendicular | G8: L - Legal I - Illegal
A9: 7 - 8 | B9: 60 | C9: 07IL007 | D9: C - Sedan | E9: SB - Setback | F9: PP - Perpendicular | G9: L
B10: 60 | C10: 99PD990 | D10: C - Sedan | E10: SB - Setback | F10: PP - Perpendicular | G10: L
B11: 60 | C11: 28LS242 | D11: C - Sedan | E11: SB - Setback | F11: PP - Perpendicular | G11: L
A12: 8 - 9 | B12: - | C12: - | D12: - | E12: - | F12: - | G12: -
A13: 9 - 10 | B13: 60 | C13: 50WV551 | D13: C - Sedan | E13: OS - On-Street | F13: PA - Parallel | G13: L
A14: 11 - 12 | B14: 60 | C14: 37HJ375 | D14: C - Sedan | E14: OS - On-Street | F14: PA - Parallel | G14: L
B15: 60 | C15: 37NF169 | D15: C - Sedan | E15: OS - On-Street | F15: PA - Parallel | G15: L
B16: 60 | C16: 73DG737 | D16: C - Sedan | E16: OS - On-Street | F16: A - 45 Degree | G16: L
B17: 60 | C17: 37NF169 | D17: C - Sedan | E17: OS - On-Street | F17: PA - Parallel | G17: L
B18: 60 | C18: 37HJ375 | D18: C - Sedan | E18: OS - On-Street | F18: PA - Parallel | G18: L
A19: 12 - 13 | B19: 60 | C19: 37RI946 | D19: C - Sedan | E19: OS - On-Street | F19: PA - Parallel | G19: L
B20: 60 | C20: 37JC072 | D20: C - Sedan | E20: OS - On-Street | F20: PA - Parallel | G20: L
A21: 13 - 14 | B21: 60 | C21: 37HJ375 | D21: C - Sedan | E21: OS - On-Street | F21: PA - Parallel | G21: L
A22: 14 - 15 | B22: 60 | C22: 37HJ375 | D22: C - Sedan | E22: OS - On-Street | F22: PA - Parallel | G22: L
A23: 15 - 16 | B23: 60 | C23: 37HJ375 | D23: C - Sedan | E23: OS - On-Street | F23: PA - Parallel | G23: L
B24: 60 | C24: 14VU114 | D24: C - Sedan | E24: OS - On-Street | F24: PA - Parallel | G24: L
A25: 16 - 17 | B25: 60 | C25: 37HJ375 | D25: C - Sedan | E25: OS - On-Street | F25: A - 45 Degree | G25: L
B26: 60 | C26: 99NM929 | D26: C - Sedan | E26: OS - On-Street | F26: A - 45 Degree | G26: L
A27: 17 - 18 | B27: 60 | C27: 37NJ375 | D27: C - Sedan | E27: OS - On-Street | F27: PA - Parallel | G27: L
B28: 60 | C28: 80TC080 | D28: C - Sedan | E28: OS - On-Street | F28: PA - Parallel | G28: L
A29: 18 - 19 | B29: 60 | C29: 37HJ375 | D29: C - Sedan | E29: OS - On-Street | F29: PA - Parallel | G29: L
A30: 19 - 20 | B30: 60 | C30: 37HJ375 | D30: C - Sedan | E30: OS - On-Street | F30: PA - Parallel | G30: L
A31: 20 - 21 | B31: 60 | C31: 37HJ375 | D31: C - Sedan | E31: OS - On-Street | F31: PA - Parallel | G31: L
A32: 21 - 22 | B32: 60 | C32: 37NJ375 | D32: C - Sedan | E32: OS - On-Street | F32: PA - Parallel | G32: L
A33: 22 - 23 | B33: 60 | C33: 03XX066 | D33: C - Sedan | E33: OS - On-Street | F33: PA - Parallel | G33: L
B34: 60 | C34: 23XB001 | D34: C - Sedan | E34: OS - On-Street | F34: PA - Parallel | G34: L

Sheet 61
A1: Parking Survey Sheet
A3: Date: | B3: 46175
A4: Route #: | B4: Mega Mall
A5: Name/Surname: | B5: _____________
A7: Time | B7: Zone | C7: License Number | D7: Vehicle Type | E7: Location | F7: Parking Method | G7: Legal/Illegal
A8: 7=7:00 14=14:00 midnight=00:00 & etc. | B8: Zone XXX | C8: 11XX111 | D8: C - Sedan T - Truck M - Motorcycle | E8: OS - On-Street FP - Footpath SB - Setback | F8: PA - Parallel A - 45 Degree PP - Perpendicular | G8: L - Legal I - Illegal
A9: 7 - 8 | B9: 61 | C9: 37FL524 | D9: C - Sedan | E9: OS - On-Street | F9: PP - Perpendicular | G9: L
A10: 8 - 9 | B10: 61 | C10: 07IL007 | D10: C - Sedan | E10: OS - On-Street | F10: PP - Perpendicular | G10: L
B11: 61 | C11: 37IA928 | D11: C - Sedan | E11: OS - On-Street | F11: PP - Perpendicular | G11: L
B12: 61 | C12: 99PD990 | D12: C - Sedan | E12: OS - On-Street | F12: PP - Perpendicular | G12: L
B13: 61 | C13: 28LS242 | D13: C - Sedan | E13: OS - On-Street | F13: PP - Perpendicular | G13: L
A14: 9 - 10 | B14: 61 | C14: 07IL007 | D14: C - Sedan | E14: SB - Setback | F14: PP - Perpendicular | G14: L
B15: 61 | C15: Е300РН | D15: C - Sedan | E15: SB - Setback | F15: PP - Perpendicular | G15: L
B16: 61 | C16: 37ZS894 | D16: C - Sedan | E16: SB - Setback | F16: PP - Perpendicular | G16: L
B17: 61 | C17: 34VF410 | D17: C - Sedan | E17: SB - Setback | F17: PP - Perpendicular | G17: L
B18: 61 | C18: 37IA928 | D18: C - Sedan | E18: SB - Setback | F18: PP - Perpendicular | G18: L
B19: 61 | C19: 71TV707 | D19: C - Sedan | E19: SB - Setback | F19: PP - Perpendicular | G19: L
B20: 61 | C20: 01VO010 | D20: C - Sedan | E20: SB - Setback | F20: PP - Perpendicular | G20: L
B21: 61 | C21: 99PD990 | D21: C - Sedan | E21: SB - Setback | F21: PP - Perpendicular | G21: L
B22: 61 | C22: 37SW353 | D22: C - Sedan | E22: SB - Setback | F22: PP - Perpendicular | G22: L
B23: 61 | C23: 35TL410 | D23: C - Sedan | E23: SB - Setback | F23: PP - Perpendicular | G23: L
B24: 61 | C24: 28LS242 | D24: C - Sedan | E24: SB - Setback | F24: PP - Perpendicular | G24: L
B25: 61 | C25: 33SS101 | D25: C - Sedan | E25: SB - Setback | F25: PP - Perpendicular | G25: L
A26: 10 - 11 | B26: 61 | C26: 37HJ375 | D26: C - Sedan | E26: OS - On-Street | F26: PA - Parallel | G26: L
B27: 61 | C27: 37HJ312 | D27: C - Sedan | E27: OS - On-Street | F27: PA - Parallel | G27: L
B28: 61 | C28: 35RN692 | D28: C - Sedan | E28: OS - On-Street | F28: A - 45 Degree | G28: L
B29: 61 | C29: 07IL007 | D29: C - Sedan | E29: OS - On-Street | F29: A - 45 Degree | G29: L
B30: 61 | C30: 88GI588 | D30: C - Sedan | E30: OS - On-Street | F30: A - 45 Degree | G30: L
B31: 61 | C31: 37KW325 | D31: C - Sedan | E31: OS - On-Street | F31: A - 45 Degree | G31: L
B32: 61 | C32: 37ZS894 | D32: C - Sedan | E32: OS - On-Street | F32: PA - Parallel | G32: L
B33: 61 | C33: 34VF410 | D33: C - Sedan | E33: OS - On-Street | F33: A - 45 Degree | G33: L
B34: 61 | C34: 51AF222 | D34: C - Sedan | E34: OS - On-Street | F34: A - 45 Degree | G34: L
B35: 61 | C35: 37IA928 | D35: C - Sedan | E35: OS - On-Street | F35: A - 45 Degree | G35: L
B36: 61 | C36: 01VO010 | D36: C - Sedan | E36: OS - On-Street | F36: A - 45 Degree | G36: L
B37: 61 | C37: 36WV366 | D37: C - Sedan | E37: OS - On-Street | F37: A - 45 Degree | G37: L
B38: 61 | C38: 35RO931 | D38: C - Sedan | E38: OS - On-Street | F38: A - 45 Degree | G38: L
... B52: 61 | C52: 97TZ007 | D52: C - Sedan | E52: OS - On-Street | F52: A - 45 Degree | G52: L
A53: 11 - 12 | B53: 61 | C53: 67XX592 | D53: C - Sedan | E53: OS - On-Street | F53: PP - Perpendicular | G53: L
B54: 61 | C54: 77IR177 | D54: C - Sedan | E54: OS - On-Street | F54: PP - Perpendicular | G54: L
B55: 61 | C55: 13SS936 | D55: C - Sedan | E55: OS - On-Street | F55: PP - Perpendicular | G55: L
...

Sheet 62
A1: Parking Survey Sheet
A3: Date: | B3: 46175
A4: Route #: | B4: Mega Mall
A5: Name/Surname: | B5: _____________
A7: Time | B7: Zone | C7: License Number | D7: Vehicle Type | E7: Location | F7: Parking Method | G7: Legal/Illegal
A8: 7=7:00 14=14:00 midnight=00:00 & etc. | B8: Zone XXX | C8: 11XX111 | D8: C - Sedan T - Truck M - Motorcycle | E8: OS - On-Street FP - Footpath SB - Setback | F8: PA - Parallel A - 45 Degree PP - Perpendicular | G8: L - Legal I - Illegal
A9: 7 - 8 | B9: 62 | C9: 37RI088 | D9: C - Sedan | E9: SB - Setback | F9: A - 45 Degree | G9: L
B10: 62 | C10: 36GG044 | D10: C - Sedan | E10: SB - Setback | F10: PP - Perpendicular | G10: L
B11: 62 | C11: 37DQ271 | D11: C - Sedan | E11: SB - Setback | F11: PP - Perpendicular | G11: L
B12: 62 | C12: 37QZ472 | D12: C - Sedan | E12: SB - Setback | F12: PP - Perpendicular | G12: L
A13: 8 - 9 | B13: 62 | C13: 37FL524 | D13: C - Sedan | E13: OS - On-Street | F13: PP - Perpendicular | G13: L
B14: 62 | C14: 37RI088 | D14: C - Sedan | E14: OS - On-Street | F14: A - 45 Degree | G14: L
A15: 9 - 10 | B15: 62 | C15: 37FL524 | D15: C - Sedan | E15: SB - Setback | F15: PP - Perpendicular | G15: L
B16: 62 | C16: 22XX332 | D16: C - Sedan | E16: SB - Setback | F16: A - 45 Degree | G16: L
B17: 62 | C17: 68DA688 | D17: C - Sedan | E17: SB - Setback | F17: A - 45 Degree | G17: L
B18: 62 | C18: 001RR20 | D18: C - Sedan | E18: SB - Setback | F18: A - 45 Degree | G18: L
B19: 62 | C19: 36OQ 971 | D19: C - Sedan | E19: SB - Setback | F19: A - 45 Degree | G19: L
A20: 10 - 11 | B20: 62 | C20: 35XS161 | D20: C - Sedan | E20: OS - On-Street | F20: A - 45 Degree | G20: L
B21: 62 | C21: 21YY200 | D21: C - Sedan | E21: OS - On-Street | F21: A - 45 Degree | G21: L
B22: 62 | C22: 77IT711 | D22: C - Sedan | E22: OS - On-Street | F22: A - 45 Degree | G22: L
B23: 62 | C23: 001RR20 | D23: C - Sedan | E23: OS - On-Street | F23: A - 45 Degree | G23: L
B24: 62 | C24: 10SO999 | D24: C - Sedan | E24: OS - On-Street | F24: A - 45 Degree | G24: L
B25: 62 | C25: 04OO464 | D25: C - Sedan | E25: OS - On-Street | F25: A - 45 Degree | G25: L
B26: 62 | C26: 36GG044 | D26: C - Sedan | E26: OS - On-Street | F26: A - 45 Degree | G26: L
B27: 62 | C27: 90SS777 | D27: C - Sedan | E27: OS - On-Street | F27: A - 45 Degree | G27: L
B28: 62 | C28: 99OB919 | D28: C - Sedan | E28: OS - On-Street | F28: A - 45 Degree | G28: L
B29: 62 | C29: 88AI088 | D29: C - Sedan | E29: OS - On-Street | F29: A - 45 Degree | G29: L
B30: 62 | C30: 86AR777 | D30: C - Sedan | E30: OS - On-Street | F30: A - 45 Degree | G30: L
B31: 62 | C31: 80ZI100 | D31: C - Sedan | E31: OS - On-Street | F31: A - 45 Degree | G31: L
B32: 62 | C32: 07OJ707 | D32: C - Sedan | E32: OS - On-Street | F32: A - 45 Degree | G32: L
B33: 62 | C33: 44KI144 | D33: C - Sedan | E33: OS - On-Street | F33: A - 45 Degree | G33: L
A34: 11 - 12 | B34: 62 | C34: 44KI144 | D34: C - Sedan | E34: OS - On-Street | F34: PP - Perpendicular | G34: L
B35: 62 | C35: 07OJ707 | D35: C - Sedan | E35: OS - On-Street | F35: PP - Perpendicular | G35: L
B36: 62 | C36: 80ZI100 | D36: C - Sedan | E36: OS - On-Street | F36: PP - Perpendicular | G36: L
B37: 62 | C37: 88AI088 | D37: C - Sedan | E37: OS - On-Street | F37: PP - Perpendicular | G37: L
B38: 62 | C38: 86AR777 | D38: C - Sedan | E38: OS - On-Street | F38: PP - Perpendicular | G38: L
B39: 62 | C39: 99OB919 | D39: C - Sedan | E39: OS - On-Street | F39: PP - Perpendicular | G39: L
B40: 62 | C40: 90SS777 | D40: C - Sedan | E40: OS - On-Street | F40: PP - Perpendicular | G40: L
B41: 62 | C41: 30GG044 | D41: C - Sedan | E41: OS - On-Street | F41: PP - Perpendicular | G41: L
B42: 62 | C42: 04OO464 | D42: C - Sedan | E42: OS - On-Street | F42: PP - Perpendicular | G42: L
...

Sheet 63
A1: Parking Survey Sheet
A3: Date: | B3: 46175
A4: Route #: | B4: Mega Mall
A5: Name/Surname: | B5: _____________
A7: Time | B7: Zone | C7: License Number | D7: Vehicle Type | E7: Location | F7: Parking Method | G7: Legal/Illegal
A8: 7=7:00 14=14:00 midnight=00:00 & etc. | B8: Zone XXX | C8: 11XX111 | D8: C - Sedan T - Truck M - Motorcycle | E8: OS - On-Street FP - Footpath SB - Setback | F8: PA - Parallel A - 45 Degree PP - Perpendicular | G8: L - Legal I - Illegal
A9: 7 - 8 | B9: 63 | C9: 90VY099 | D9: T - Truck | E9: OS - On-Street | F9: PA - Parallel | G9: L
A10: 8 - 9 | B10: 63 | C10: 04OO464 | D10: C - Sedan | E10: OS - On-Street | F10: PP - Perpendicular | G10: L
B11: 63 | C11: 36GG044 | D11: C - Sedan | E11: OS - On-Street | F11: PP - Perpendicular | G11: L
B12: 63 | C12: 37QZ472 | D12: C - Sedan | E12: OS - On-Street | F12: A - 45 Degree | G12: L
B13: 63 | C13: 33PR333 | D13: C - Sedan | E13: OS - On-Street | F13: A - 45 Degree | G13: L
A14: 9 - 10 | B14: 63 | C14: 10SO 999 | D14: C - Sedan | E14: SB - Setback | F14: PP - Perpendicular | G14: L
B15: 63 | C15: 04OO464 | D15: C - Sedan | E15: SB - Setback | F15: PP - Perpendicular | G15: L
B16: 63 | C16: 36GG044 | D16: C - Sedan | E16: SB - Setback | F16: PP - Perpendicular | G16: L
A17: 10 - 11 | B17: 63 | C17: 08DC808 | D17: C - Sedan | E17: OS - On-Street | F17: A - 45 Degree | G17: L
B18: 63 | C18: 88DC808 | D18: C - Sedan | E18: OS - On-Street | F18: A - 45 Degree | G18: L
B19: 63 | C19: 90VY099 | D19: T - Truck | E19: OS - On-Street | F19: PA - Parallel | G19: L
A20: 11 - 12 | B20: 63 | C20: no number | D20: C - Sedan | E20: OS - On-Street | F20: PA - Parallel | G20: L
B21: 63 | C21: 90VV099 | D21: T - Truck | E21: OS - On-Street | F21: PA - Parallel | G21: L
A22: 12 - 13 | B22: 63 | C22: 08GC808 | D22: C - Sedan | E22: OS - On-Street | F22: PA - Parallel | G22: L
B23: 63 | C23: 88DC808 | D23: C - Sedan | E23: OS - On-Street | F23: A - 45 Degree | G23: L
B24: 63 | C24: 90VY099 | D24: T - Truck | E24: OS - On-Street | F24: PA - Parallel | G24: L
A25: 13 - 14 | B25: 63 | C25: 13SL110 | D25: C - Sedan | E25: OS - On-Street | F25: PA - Parallel | G25: L
B26: 63 | C26: 09II090 | D26: C - Sedan | E26: OS - On-Street | F26: PA - Parallel | G26: L
B27: 63 | C27: 90VY099 | D27: T - Truck | E27: OS - On-Street | F27: PA - Parallel | G27: L
A28: 14 - 15 | B28: 63 | C28: 08DC808 | D28: C - Sedan | E28: OS - On-Street | F28: A - 45 Degree | G28: L
B29: 63 | C29: 88DC808 | D29: C - Sedan | E29: OS - On-Street | F29: A - 45 Degree | G29: L
B30: 63 | C30: 777AG17 | D30: C - Sedan | E30: OS - On-Street | F30: PA - Parallel | G30: L
B31: 63 | C31: 99VY099 | D31: T - Truck | E31: OS - On-Street | F31: PA - Parallel | G31: L
A32: 15 - 16 | B32: 63 | C32: 90VY099 | D32: T - Truck | E32: OS - On-Street | F32: PA - Parallel | G32: L
A33: 16 - 17 | B33: 63 | C33: 08DC808 | D33: C - Sedan | E33: OS - On-Street | F33: A - 45 Degree | G33: L
B34: 63 | C34: 88DC808 | D34: C - Sedan | E34: OS - On-Street | F34: A - 45 Degree | G34: L
B35: 63 | C35: 99VY099 | D35: C - Sedan | E35: OS - On-Street | F35: PA - Parallel | G35: L
A36: 17 - 18 | B36: 63 | C36: 37RE037 | D36: C - Sedan | E36: OS - On-Street | F36: PP - Perpendicular | G36: L
B37: 63 | C37: 88DC808 | D37: C - Sedan | E37: OS - On-Street | F37: PP - Perpendicular | G37: L
A38: 18 - 19 | B38: 63 | C38: 08DC808 | D38: C - Sedan | E38: OS - On-Street | F38: A - 45 Degree | G38: L
B39: 63 | C39: 88DC808 | D39: C - Sedan | E39: OS - On-Street | F39: A - 45 Degree | G39: L
B40: 63 | C40: 86CM7777 | D40: C - Sedan | E40: OS - On-Street | F40: PA - Parallel | G40: L
B41: 63 | C41: 08AA202 | D41: C - Sedan | E41: OS - On-Street | F41: PA - Parallel | G41: L
B42: 63 | C42: 86AR777 | D42: C - Sedan | E42: OS - On-Street | F42: PA - Parallel | G42: L
...

Sheet 64
A1: Parking Survey Sheet
A3: Date: | B3: 46175
A4: Route #: | B4: Mega Mall
A5: Name/Surname: | B5: _____________
A7: Time | B7: Zone | C7: License Number | D7: Vehicle Type | E7: Location | F7: Parking Method | G7: Legal/Illegal
A8: 7=7:00 14=14:00 midnight=00:00 & etc. | B8: Zone XXX | C8: 11XX111 | D8: C - Sedan T - Truck M - Motorcycle | E8: OS - On-Street FP - Footpath SB - Setback | F8: PA - Parallel A - 45 Degree PP - Perpendicular | G8: L - Legal I - Illegal
A9: 7 - 8 | B9: - | C9: - | D9: - | E9: - | F9: - | G9: -
A10: 8 - 9 | B10: 64 | C10: 02SU791 | D10: C - Sedan | E10: OS - On-Street | F10: PA - Parallel | G10: L
B11: 64 | C11: 34ST490 | D11: C - Sedan | E11: OS - On-Street | F11: PA - Parallel | G11: L
A12: 9 - 10 | B12: 64 | C12: 91XO991 | D12: C - Sedan | E12: OS - On-Street | F12: PA - Parallel | G12: L
B13: 64 | C13: 34RC463 | D13: C - Sedan | E13: OS - On-Street | F13: PA - Parallel | G13: L
B14: 64 | C14: 37KT085 | D14: C - Sedan | E14: OS - On-Street | F14: PA - Parallel | G14: L
B15: 64 | C15: 30NN777 | D15: C - Sedan | E15: OS - On-Street | F15: PA - Parallel | G15: L
A16: 10 - 11 | B16: 64 | C16: 37ER139 | D16: C - Sedan | E16: OS - On-Street | F16: PA - Parallel | G16: L
B17: 64 | C17: 91XO991 | D17: C - Sedan | E17: OS - On-Street | F17: PA - Parallel | G17: L
B18: 64 | C18: 37RZ190 | D18: C - Sedan | E18: OS - On-Street | F18: PA - Parallel | G18: L
A19: 11 - 12 | B19: 64 | C19: 37IA352 | D19: C - Sedan | E19: OS - On-Street | F19: PP - Perpendicular | G19: L
B20: 64 | C20: 90GC101 | D20: C - Sedan | E20: OS - On-Street | F20: PP - Perpendicular | G20: L
B21: 64 | C21: 37PR656 | D21: C - Sedan | E21: OS - On-Street | F21: PP - Perpendicular | G21: L
B22: 64 | C22: 37HP716 | D22: C - Sedan | E22: OS - On-Street | F22: PA - Parallel | G22: L
B23: 64 | C23: 35XS841 | D23: C - Sedan | E23: OS - On-Street | F23: PA - Parallel | G23: L
B24: 64 | C24: 09RV003 | D24: C - Sedan | E24: OS - On-Street | F24: PA - Parallel | G24: L
B25: 64 | C25: 37HK906 | D25: C - Sedan | E25: OS - On-Street | F25: PA - Parallel | G25: L
B26: 64 | C26: 91XO991 | D26: C - Sedan | E26: OS - On-Street | F26: PA - Parallel | G26: L
B27: 64 | C27: 37ER139 | D27: C - Sedan | E27: OS - On-Street | F27: PA - Parallel | G27: L
B28: 64 | C28: 99JJ933 | D28: C - Sedan | E28: OS - On-Street | F28: PA - Parallel | G28: L
A29: 12 - 13 | B29: 64 | C29: 99JJ933 | D29: C - Sedan | E29: OS - On-Street | F29: PA - Parallel | G29: L
B30: 64 | C30: 37ER139 | D30: C - Sedan | E30: OS - On-Street | F30: PA - Parallel | G30: L
B31: 64 | C31: 91XO991 | D31: C - Sedan | E31: OS - On-Street | F31: PA - Parallel | G31: L
B32: 64 | C32: 77HH045 | D32: C - Sedan | E32: OS - On-Street | F32: PA - Parallel | G32: L
A33: 13 - 14 | B33: 64 | C33: 37ER139 | D33: C - Sedan | E33: OS - On-Street | F33: PA - Parallel | G33: L
B34: 64 | C34: 37AQ439 | D34: C - Sedan | E34: OS - On-Street | F34: PA - Parallel | G34: L
B35: 64 | C35: 37KZ571 | D35: C - Sedan | E35: OS - On-Street | F35: PA - Parallel | G35: L
B36: 64 | C36: 28D008AM | D36: C - Sedan | E36: OS - On-Street | F36: PA - Parallel | G36: L
B37: 64 | C37: 37OQ565 | D37: C - Sedan | E37: OS - On-Street | F37: PA - Parallel | G37: L
A38: 14 - 15 | B38: 64 | C38: 01JI505 | D38: C - Sedan | E38: OS - On-Street | F38: PA - Parallel | G38: L
B39: 64 | C39: 70MM701 | D39: C - Sedan | E39: OS - On-Street | F39: PA - Parallel | G39: L
B40: 64 | C40: 55MQ155 | D40: C - Sedan | E40: OS - On-Street | F40: PA - Parallel | G40: L
B41: 64 | C41: 88MB688 | D41: C - Sedan | E41: OS - On-Street | F41: PA - Parallel | G41: L
B42: 64 | C42: 8693FE | D42: C - Sedan | E42: OS - On-Street | F42: PA - Parallel | G42: L
...

Sheet 65
A1: Parking Survey Sheet
A3: Date: | B3: 46175
A4: Route #: | B4: Mega Mall
A5: Name/Surname: | B5: _____________
A7: Time | B7: Zone | C7: License Number | D7: Vehicle Type | E7: Location | F7: Parking Method | G7: Legal/Illegal
A8: 7=7:00 14=14:00 midnight=00:00 & etc. | B8: Zone XXX | C8: 11XX111 | D8: C - Sedan T - Truck M - Motorcycle | E8: OS - On-Street FP - Footpath SB - Setback | F8: PA - Parallel A - 45 Degree PP - Perpendicular | G8: L - Legal I - Illegal
A9: 7 - 8 | B9: 65 | C9: 30NN777 | D9: C - Sedan | E9: SB - Setback | F9: PP - Perpendicular | G9: L
B10: 65 | C10: 90VV555 | D10: C - Sedan | E10: OS - On-Street | F10: PP - Perpendicular | G10: L
A11: 8 - 9 | B11: 65 | C11: 30NN777 | D11: C - Sedan | E11: SB - Setback | F11: PP - Perpendicular | G11: L
B12: 65 | C12: 90VV555 | D12: C - Sedan | E12: SB - Setback | F12: PP - Perpendicular | G12: L
A13: 9 - 10 | B13: 65 | C13: 37IA352 | D13: C - Sedan | E13: SB - Setback | F13: PP - Perpendicular | G13: L
B14: 65 | C14: 57ZX007 | D14: C - Sedan | E14: SB - Setback | F14: PP - Perpendicular | G14: L
B15: 65 | C15: 36NA858 | D15: C - Sedan | E15: SB - Setback | F15: PP - Perpendicular | G15: L
B16: 65 | C16: 35TG982 | D16: C - Sedan | E16: SB - Setback | F16: PP - Perpendicular | G16: L
B17: 65 | C17: 35QG846 | D17: C - Sedan | E17: SB - Setback | F17: PP - Perpendicular | G17: L
B18: 65 | C18: 90VV555 | D18: C - Sedan | E18: SB - Setback | F18: PP - Perpendicular | G18: L
B19: 65 | C19: 37QU344 | D19: C - Sedan | E19: SB - Setback | F19: PP - Perpendicular | G19: L
B20: 65 | C20: 020BG01 | D20: C - Sedan | E20: SB - Setback | F20: PP - Perpendicular | G20: L
B21: 65 | C21: 35MV500 | D21: C - Sedan | E21: SB - Setback | F21: PP - Perpendicular | G21: L
A22: 10 - 11 | B22: 65 | C22: 10RE001 | D22: C - Sedan | E22: OS - On-Street | F22: A - 45 Degree | G22: L
B23: 65 | C23: 90GC101 | D23: C - Sedan | E23: OS - On-Street | F23: A - 45 Degree | G23: L
B24: 65 | C24: 37GA822 | D24: C - Sedan | E24: OS - On-Street | F24: A - 45 Degree | G24: L
B25: 65 | C25: 37PR656 | D25: C - Sedan | E25: OS - On-Street | F25: PA - Parallel | G25: L
B26: 65 | C26: 37IA352 | D26: C - Sedan | E26: OS - On-Street | F26: A - 45 Degree | G26: L
B27: 65 | C27: 75LF075 | D27: C - Sedan | E27: OS - On-Street | F27: PA - Parallel | G27: L
B28: 65 | C28: 36UR091 | D28: C - Sedan | E28: OS - On-Street | F28: A - 45 Degree | G28: L
B29: 65 | C29: 08LL101 | D29: C - Sedan | E29: OS - On-Street | F29: A - 45 Degree | G29: L
B30: 65 | C30: 36NA858 | D30: C - Sedan | E30: OS - On-Street | F30: A - 45 Degree | G30: L
B31: 65 | C31: 35TG982 | D31: C - Sedan | E31: OS - On-Street | F31: A - 45 Degree | G31: L
B32: 65 | C32: 37MG865 | D32: C - Sedan | E32: OS - On-Street | F32: A - 45 Degree | G32: L
B33: 65 | C33: 37TV671 | D33: C - Sedan | E33: OS - On-Street | F33: A - 45 Degree | G33: L
B34: 65 | C34: 87HO877 | D34: C - Sedan | E34: OS - On-Street | F34: A - 45 Degree | G34: L
B35: 65 | C35: 90VV555 | D35: C - Sedan | E35: OS - On-Street | F35: A - 45 Degree | G35: L
A36: 11 - 12 | B36: 65 | C36: 37KV732 | D36: C - Sedan | E36: OS - On-Street | F36: PP - Perpendicular | G36: L
B37: 65 | C37: 87HO877 | D37: C - Sedan | E37: OS - On-Street | F37: PP - Perpendicular | G37: L
B38: 65 | C38: 36SN838 | D38: C - Sedan | E38: OS - On-Street | F38: PP - Perpendicular | G38: L
B39: 65 | C39: 37MJ865 | D39: C - Sedan | E39: OS - On-Street | F39: PP - Perpendicular | G39: L
B40: 65 | C40: 35TG982 | D40: C - Sedan | E40: OS - On-Street | F40: PP - Perpendicular | G40: L
B41: 65 | C41: 36NA858 | D41: C - Sedan | E41: OS - On-Street | F41: PP - Perpendicular | G41: L
B42: 65 | C42: 33SS232 | D42: C - Sedan | E42: OS - On-Street | F42: PP - Perpendicular | G42: L
...

Sheet 66
A1: Parking Survey Sheet
A3: Date: | B3: 46175
A4: Route #: | B4: Mega Mall
A5: Name/Surname: | B5: _____________
A7: Time | B7: Zone | C7: License Number | D7: Vehicle Type | E7: Location | F7: Parking Method | G7: Legal/Illegal
A8: 7=7:00 14=14:00 midnight=00:00 & etc. | B8: Zone XXX | C8: 11XX111 | D8: C - Sedan T - Truck M - Motorcycle | E8: OS - On-Street FP - Footpath SB - Setback | F8: PA - Parallel A - 45 Degree PP - Perpendicular | G8: L - Legal I - Illegal
A9: 7 - 8 | B9: 66 | C9: 88ZX909 | D9: C - Sedan | E9: OS - On-Street | F9: PP - Perpendicular | G9: L
B10: 66 | C10: 11LL199 | D10: C - Sedan | E10: OS - On-Street | F10: A - 45 Degree | G10: L
B11: 66 | C11: 06UU231 | D11: C - Sedan | E11: OS - On-Street | F11: A - 45 Degree | G11: L
B12: 66 | C12: 35FF418 | D12: C - Sedan | E12: SB - Setback | F12: A - 45 Degree | G12: L
B13: 66 | C13: 077RO01 | D13: C - Sedan | E13: SB - Setback | F13: PP - Perpendicular | G13: L
A14: 8 - 9 | B14: 66 | C14: 88ZX909 | D14: C - Sedan | E14: SB - Setback | F14: PP - Perpendicular | G14: L
B15: 66 | C15: 36VZ164 | D15: T - Truck | E15: SB - Setback | F15: PP - Perpendicular | G15: L
B16: 66 | C16: 11LL199 | D16: C - Sedan | E16: SB - Setback | F16: A - 45 Degree | G16: L
B17: 66 | C17: 34QQ734 | D17: C - Sedan | E17: SB - Setback | F17: A - 45 Degree | G17: L
B18: 66 | C18: 06UU231 | D18: C - Sedan | E18: SB - Setback | F18: A - 45 Degree | G18: L
B19: 66 | C19: 37SD003 | D19: C - Sedan | E19: SB - Setback | F19: A - 45 Degree | G19: L
B20: 66 | C20: 87KN987 | D20: C - Sedan | E20: SB - Setback | F20: A - 45 Degree | G20: L
B21: 66 | C21: 30PV020 | D21: C - Sedan | E21: SB - Setback | F21: A - 45 Degree | G21: L
B22: 66 | C22: 33PU148 | D22: C - Sedan | E22: SB - Setback | F22: A - 45 Degree | G22: L
B23: 66 | C23: 37DW348 | D23: C - Sedan | E23: SB - Setback | F23: A - 45 Degree | G23: L
B24: 66 | C24: 37CE212 | D24: C - Sedan | E24: SB - Setback | F24: A - 45 Degree | G24: L
B25: 66 | C25: 37QH790 | D25: C - Sedan | E25: SB - Setback | F25: A - 45 Degree | G25: L
A26: 9 - 10 | B26: 66 | C26: 88ZX909 | D26: C - Sedan | E26: SB - Setback | F26: A - 45 Degree | G26: L
B27: 66 | C27: 25GV005 | D27: C - Sedan | E27: SB - Setback | F27: A - 45 Degree | G27: L
B28: 66 | C28: О448ХА | D28: C - Sedan | E28: SB - Setback | F28: A - 45 Degree | G28: L
B29: 66 | C29: 44QU144 | D29: C - Sedan | E29: SB - Setback | F29: PP - Perpendicular | G29: L
B30: 66 | C30: 88ZV848 | D30: C - Sedan | E30: SB - Setback | F30: A - 45 Degree | G30: L
B31: 66 | C31: 11LL199 | D31: C - Sedan | E31: SB - Setback | F31: A - 45 Degree | G31: L
B32: 66 | C32: 824DA61 | D32: C - Sedan | E32: SB - Setback | F32: A - 45 Degree | G32: L
B33: 66 | C33: 35QG756 | D33: C - Sedan | E33: SB - Setback | F33: A - 45 Degree | G33: L
B34: 66 | C34: 34QQ734 | D34: C - Sedan | E34: SB - Setback | F34: A - 45 Degree | G34: L
B35: 66 | C35: 11AZ110 | D35: C - Sedan | E35: SB - Setback | F35: A - 45 Degree | G35: L
B36: 66 | C36: 06UU231 | D36: C - Sedan | E36: SB - Setback | F36: A - 45 Degree | G36: L
B37: 66 | C37: 206HJ61 | D37: C - Sedan | E37: SB - Setback | F37: A - 45 Degree | G37: L
B38: 66 | C38: 37NI984 | D38: C - Sedan | E38: SB - Setback | F38: A - 45 Degree | G38: L
... B48: 66 | C48: 37QH790 | D48: C - Sedan | E48: SB - Setback | F48: PP - Perpendicular | G48: L
A49: 10 - 11 | B49: 66 | C49: 06VH606 | D49: C - Sedan | E49: OS - On-Street | F49: A - 45 Degree | G49: L
B50: 66 | C50: 15GL444 | D50: C - Sedan | E50: OS - On-Street | F50: A - 45 Degree | G50: L
B51: 66 | C51: 88ZX909 | D51: C - Sedan | E51: OS - On-Street | F51: A - 45 Degree | G51: L
...

Sheet 67
A1: Parking Survey Sheet
A3: Date: | B3: 46175
A4: Route #: | B4: Mega Mall
A5: Name/Surname: | B5: _____________
A7: Time | B7: Zone | C7: License Number | D7: Vehicle Type | E7: Location | F7: Parking Method | G7: Legal/Illegal
A8: 7=7:00 14=14:00 midnight=00:00 & etc. | B8: Zone XXX | C8: 11XX111 | D8: C - Sedan T - Truck M - Motorcycle | E8: OS - On-Street FP - Footpath SB - Setback | F8: PA - Parallel A - 45 Degree PP - Perpendicular | G8: L - Legal I - Illegal
A9: 7 - 8 | B9: - | C9: - | D9: - | E9: - | F9: - | G9: -
A10: 8 - 9 | B10: 67 | C10: 71TI701 | D10: C - Sedan | E10: OS - On-Street | F10: A - 45 Degree | G10: L
B11: 67 | C11: 37RB427 | D11: C - Sedan | E11: OS - On-Street | F11: A - 45 Degree | G11: L
A12: 9 - 10 | B12: 67 | C12: 71TI701 | D12: C - Sedan | E12: SB - Setback | F12: A - 45 Degree | G12: L
B13: 67 | C13: 47HH044 | D13: C - Sedan | E13: SB - Setback | F13: A - 45 Degree | G13: L
B14: 67 | C14: 99YH199 | D14: C - Sedan | E14: SB - Setback | F14: A - 45 Degree | G14: L
B15: 67 | C15: 65OS199 | D15: C - Sedan | E15: SB - Setback | F15: A - 45 Degree | G15: L
B16: 67 | C16: 37VL773 | D16: C - Sedan | E16: SB - Setback | F16: A - 45 Degree | G16: L
B17: 67 | C17: 54LM548 | D17: C - Sedan | E17: SB - Setback | F17: A - 45 Degree | G17: L
A18: 10 - 11 | B18: 67 | C18: 71TI701 | D18: C - Sedan | E18: OS - On-Street | F18: A - 45 Degree | G18: L
B19: 67 | C19: 47HH044 | D19: C - Sedan | E19: OS - On-Street | F19: A - 45 Degree | G19: L
B20: 67 | C20: 001DD44 | D20: C - Sedan | E20: OS - On-Street | F20: A - 45 Degree | G20: L
B21: 67 | C21: 99YH199 | D21: C - Sedan | E21: OS - On-Street | F21: A - 45 Degree | G21: L
B22: 67 | C22: 35TN683 | D22: C - Sedan | E22: OS - On-Street | F22: A - 45 Degree | G22: L
B23: 67 | C23: 37LV773 | D23: C - Sedan | E23: OS - On-Street | F23: A - 45 Degree | G23: L
B24: 67 | C24: 54LM548 | D24: C - Sedan | E24: OS - On-Street | F24: A - 45 Degree | G24: L
B25: 67 | C25: 28QD029 | D25: C - Sedan | E25: OS - On-Street | F25: A - 45 Degree | G25: L
A26: 11 - 12 | B26: 67 | C26: 54LM548 | D26: C - Sedan | E26: OS - On-Street | F26: A - 45 Degree | G26: L
B27: 67 | C27: 37LV773 | D27: C - Sedan | E27: OS - On-Street | F27: A - 45 Degree | G27: L
B28: 67 | C28: 37TN683 | D28: C - Sedan | E28: OS - On-Street | F28: A - 45 Degree | G28: L
B29: 67 | C29: 99YH199 | D29: C - Sedan | E29: OS - On-Street | F29: A - 45 Degree | G29: L
B30: 67 | C30: 90MR909 | D30: C - Sedan | E30: OS - On-Street | F30: A - 45 Degree | G30: L
B31: 67 | C31: 47HH044 | D31: C - Sedan | E31: OS - On-Street | F31: A - 45 Degree | G31: L
B32: 67 | C32: 71TI701 | D32: C - Sedan | E32: OS - On-Street | F32: A - 45 Degree | G32: L
A33: 12 - 13 | B33: 67 | C33: 54 LM548 | D33: C - Sedan | E33: OS - On-Street | F33: A - 45 Degree | G33: L
B34: 67 | C34: 37LV773 | D34: C - Sedan | E34: OS - On-Street | F34: A - 45 Degree | G34: L
B35: 67 | C35: 66NN669 | D35: C - Sedan | E35: OS - On-Street | F35: A - 45 Degree | G35: L
B36: 67 | C36: 99YH199 | D36: C - Sedan | E36: OS - On-Street | F36: A - 45 Degree | G36: L
B37: 67 | C37: 19NN777 | D37: C - Sedan | E37: OS - On-Street | F37: A - 45 Degree | G37: L
B38: 67 | C38: 47HH044 | D38: C - Sedan | E38: OS - On-Street | F38: PA - Parallel | G38: L
B39: 67 | C39: 71TI701 | D39: C - Sedan | E39: OS - On-Street | F39: A - 45 Degree | G39: L
A40: 13 - 14 | B40: 67 | C40: 10OT099 | D40: C - Sedan | E40: OS - On-Street | F40: A - 45 Degree | G40: L
B41: 67 | C41: 37LV773 | D41: C - Sedan | E41: OS - On-Street | F41: A - 45 Degree | G41: L
B42: 67 | C42: 37TJ380 | D42: C - Sedan | E42: FP - Footpath | F42: A - 45 Degree | G42: L
...

Sheet 68
A1: Parking Survey Sheet
A3: Date: | B3: 46175
A4: Route #: | B4: Mega Mall
A5: Name/Surname: | B5: _____________
A7: Time | B7: Zone | C7: License Number | D7: Vehicle Type | E7: Location | F7: Parking Method | G7: Legal/Illegal
A8: 7=7:00 14=14:00 midnight=00:00 & etc. | B8: Zone XXX | C8: 11XX111 | D8: C - Sedan T - Truck M - Motorcycle | E8: OS - On-Street FP - Footpath SB - Setback | F8: PA - Parallel A - 45 Degree PP - Perpendicular | G8: L - Legal I - Illegal
A9: 7 - 8 | B9: 68 | C9: 12AH112 | D9: C - Sedan | E9: SB - Setback | F9: PP - Perpendicular | G9: L
B10: 68 | C10: 333XX37 | D10: C - Sedan | E10: SB - Setback | F10: A - 45 Degree | G10: L
A11: 8 - 9 | B11: - | C11: - | D11: - | E11: - | F11: - | G11: -
A12: 9 - 10 | B12: 68 | C12: 34RT069 | D12: C - Sedan | E12: OS - On-Street | F12: PA - Parallel | G12: L
B13: 68 | C13: 50CC066 | D13: C - Sedan | E13: OS - On-Street | F13: PA - Parallel | G13: L
B14: 68 | C14: 97ZQ777 | D14: C - Sedan | E14: OS - On-Street | F14: PA - Parallel | G14: L
A15: 10 - 11 | B15: 68 | C15: 97ZQ777 | D15: C - Sedan | E15: OS - On-Street | F15: PA - Parallel | G15: L
B16: 68 | C16: 10IA110 | D16: C - Sedan | E16: OS - On-Street | F16: PA - Parallel | G16: L
B17: 68 | C17: 34PT069 | D17: C - Sedan | E17: OS - On-Street | F17: PA - Parallel | G17: L
B18: 68 | C18: 37JZ498 | D18: C - Sedan | E18: OS - On-Street | F18: PA - Parallel | G18: L
A19: 11 - 12 | B19: 68 | C19: 97ZQ777 | D19: C - Sedan | E19: OS - On-Street | F19: PA - Parallel | G19: L
B20: 68 | C20: 10IA110 | D20: C - Sedan | E20: OS - On-Street | F20: PA - Parallel | G20: L
B21: 68 | C21: 34PT069 | D21: C - Sedan | E21: OS - On-Street | F21: PA - Parallel | G21: L
B22: 68 | C22: 37JZ498 | D22: C - Sedan | E22: OS - On-Street | F22: PA - Parallel | G22: L
A23: 12 - 13 | B23: 68 | C23: 97ZQ777 | D23: C - Sedan | E23: OS - On-Street | F23: PA - Parallel | G23: L
B24: 68 | C24: 10IA110 | D24: C - Sedan | E24: OS - On-Street | F24: PA - Parallel | G24: L
B25: 68 | C25: 34PT069 | D25: C - Sedan | E25: OS - On-Street | F25: PA - Parallel | G25: L
B26: 68 | C26: 37JZ498 | D26: C - Sedan | E26: OS - On-Street | F26: PA - Parallel | G26: L
A27: 13 - 14 | B27: 68 | C27: 10IA110 | D27: C - Sedan | E27: OS - On-Street | F27: PA - Parallel | G27: L
B28: 68 | C28: 34PT069 | D28: C - Sedan | E28: OS - On-Street | F28: PA - Parallel | G28: L
B29: 68 | C29: 37JZ498 | D29: C - Sedan | E29: OS - On-Street | F29: PA - Parallel | G29: L
A30: 14 - 15 | B30: 68 | C30: 97ZQ777 | D30: C - Sedan | E30: OS - On-Street | F30: PA - Parallel | G30: L
B31: 68 | C31: 10IA110 | D31: C - Sedan | E31: OS - On-Street | F31: PA - Parallel | G31: L
B32: 68 | C32: 37NO669 | D32: C - Sedan | E32: OS - On-Street | F32: PP - Perpendicular | G32: L
B33: 68 | C33: 37JZ498 | D33: C - Sedan | E33: OS - On-Street | F33: PA - Parallel | G33: L
A34: 15 - 16 | B34: 68 | C34: 10IA110 | D34: C - Sedan | E34: OS - On-Street | F34: PA - Parallel | G34: L
B35: 68 | C35: 37JZ498 | D35: C - Sedan | E35: OS - On-Street | F35: PA - Parallel | G35: L
A36: 16 - 17 | B36: 68 | C36: 10AI110 | D36: C - Sedan | E36: OS - On-Street | F36: PA - Parallel | G36: L
B37: 68 | C37: 97ZQ777 | D37: C - Sedan | E37: OS - On-Street | F37: PA - Parallel | G37: L
B38: 68 | C38: 34PT069 | D38: C - Sedan | E38: OS - On-Street | F38: PA - Parallel | G38: L
B39: 68 | C39: 37JZ498 | D39: C - Sedan | E39: OS - On-Street | F39: PA - Parallel | G39: L
B40: 68 | C40: 35GV931 | D40: C - Sedan | E40: OS - On-Street | F40: PA - Parallel | G40: L
A41: 17 - 18 | B41: 68 | C41: 10IA110 | D41: C - Sedan | E41: OS - On-Street | F41: PA - Parallel | G41: L
B42: 68 | C42: 34PT069 | D42: C - Sedan | E42: OS - On-Street | F42: PA - Parallel | G42: L
...

Sheet 69
A1: Parking Survey Sheet
A3: Date: | B3: 46175
A4: Route #: | B4: Mega Mall
A5: Name/Surname: | B5: _____________
A7: Time | B7: Zone | C7: License Number | D7: Vehicle Type | E7: Location | F7: Parking Method | G7: Legal/Illegal
A8: 7=7:00 14=14:00 midnight=00:00 & etc. | B8: Zone XXX | C8: 11XX111 | D8: C - Sedan T - Truck M - Motorcycle | E8: OS - On-Street FP - Footpath SB - Setback | F8: PA - Parallel A - 45 Degree PP - Perpendicular | G8: L - Legal I - Illegal
A9: 7 - 8 | B9: 69 | C9: 70CC075 | D9: C - Sedan | E9: SB - Setback | F9: A - 45 Degree | G9: L
B10: 69 | C10: 37ZR224 | D10: C - Sedan | E10: SB - Setback | F10: A - 45 Degree | G10: L
B11: 69 | C11: 37MH952 | D11: C - Sedan | E11: SB - Setback | F11: A - 45 Degree | G11: L
A12: 8 - 9 | B12: 69 | C12: 71IP001 | D12: C - Sedan | E12: OS - On-Street | F12: A - 45 Degree | G12: L
B13: 69 | C13: 37NH608 | D13: C - Sedan | E13: OS - On-Street | F13: A - 45 Degree | G13: L
B14: 69 | C14: 01QK055 | D14: C - Sedan | E14: OS - On-Street | F14: A - 45 Degree | G14: L
B15: 69 | C15: 37HO296 | D15: C - Sedan | E15: OS - On-Street | F15: A - 45 Degree | G15: L
B16: 69 | C16: 55XR554 | D16: C - Sedan | E16: OS - On-Street | F16: A - 45 Degree | G16: L
B17: 69 | C17: 36VC014 | D17: C - Sedan | E17: OS - On-Street | F17: A - 45 Degree | G17: L
B18: 69 | C18: 07CC101 | D18: C - Sedan | E18: OS - On-Street | F18: A - 45 Degree | G18: L
A19: 9 - 10 | B19: 69 | C19: 07CC101 | D19: C - Sedan | E19: SB - Setback | F19: A - 45 Degree | G19: L
B20: 69 | C20: 10GM300 | D20: C - Sedan | E20: SB - Setback | F20: A - 45 Degree | G20: L
B21: 69 | C21: 04AG044 | D21: C - Sedan | E21: SB - Setback | F21: A - 45 Degree | G21: L
B22: 69 | C22: 34TM867 | D22: C - Sedan | E22: SB - Setback | F22: A - 45 Degree | G22: L
B23: 69 | C23: 01GD015 | D23: C - Sedan | E23: SB - Setback | F23: A - 45 Degree | G23: L
B24: 69 | C24: 37MA228 | D24: C - Sedan | E24: SB - Setback | F24: A - 45 Degree | G24: L
B25: 69 | C25: 17QU017 | D25: C - Sedan | E25: SB - Setback | F25: A - 45 Degree | G25: L
B26: 69 | C26: 60LM088 | D26: C - Sedan | E26: SB - Setback | F26: A - 45 Degree | G26: L
B27: 69 | C27: 10NR500 | D27: C - Sedan | E27: SB - Setback | F27: A - 45 Degree | G27: L
B28: 69 | C28: 01DR044 | D28: C - Sedan | E28: SB - Setback | F28: A - 45 Degree | G28: L
A29: 10 - 11 | B29: 69 | C29: 01DR044 | D29: C - Sedan | E29: OS - On-Street | F29: PP - Perpendicular | G29: L
B30: 69 | C30: 10NR | D30: C - Sedan | E30: OS - On-Street | F30: A - 45 Degree | G30: L
B31: 69 | C31: 60LM088 | D31: C - Sedan | E31: OS - On-Street | F31: A - 45 Degree | G31: L
B32: 69 | C32: 71JZ007 | D32: C - Sedan | E32: OS - On-Street | F32: A - 45 Degree | G32: L
B33: 69 | C33: 17QU017 | D33: C - Sedan | E33: OS - On-Street | F33: A - 45 Degree | G33: L
B34: 69 | C34: 37EP315 | D34: C - Sedan | E34: OS - On-Street | F34: A - 45 Degree | G34: L
B35: 69 | C35: 50AA909 | D35: C - Sedan | E35: OS - On-Street | F35: A - 45 Degree | G35: L
B36: 69 | C36: 08UJ080 | D36: C - Sedan | E36: OS - On-Street | F36: A - 45 Degree | G36: L
B37: 69 | C37: 37PY649 | D37: C - Sedan | E37: OS - On-Street | F37: A - 45 Degree | G37: L
B38: 69 | C38: 04AG044 | D38: C - Sedan | E38: OS - On-Street | F38: A - 45 Degree | G38: L
B39: 69 | C39: 07NE077 | D39: C - Sedan | E39: OS - On-Street | F39: A - 45 Degree | G39: L
B40: 69 | C40: 07CC101 | D40: C - Sedan | E40: OS - On-Street | F40: A - 45 Degree | G40: L
B41: 69 | C41: 23AN300 | D41: C - Sedan | E41: OS - On-Street | F41: PA - Parallel | G41: L
A42: 11 - 12 | B42: 69 | C42: 01DR044 | D42: C - Sedan | E42: OS - On-Street | F42: PP - Perpendicular | G42: L
...

Sheet P
A1: Parking Survey Sheet
A3: Date: | B3: 46175
A4: Route #: | B4: Mega Mall
A5: Name/Surname: | B5: _____________
A7: Time | B7: Zone | C7: License Number | D7: Vehicle Type | E7: Location | F7: Parking Method | G7: Legal/Illegal
A8: 7=7:00 14=14:00 midnight=00:00 & etc. | B8: Zone XXX | C8: 11XX111 | D8: C - Sedan T - Truck M - Motorcycle | E8: OS - On-Street FP - Footpath SB - Setback | F8: PA - Parallel A - 45 Degree PP - Perpendicular | G8: L - Legal I - Illegal
A9: 7 - 8 | B9: P | C9: 37SG316 | D9: C - Sedan | E9: SB - Setback | F9: PP - Perpendicular | G9: L
B10: P | C10: 13SL038 | D10: C - Sedan | E10: SB - Setback | F10: PP - Perpendicular | G10: L
B11: P | C11: 37AC595 | D11: C - Sedan | E11: SB - Setback | F11: PP - Perpendicular | G11: L
B12: P | C12: 90XY100 | D12: C - Sedan | E12: SB - Setback | F12: PP - Perpendicular | G12: L
B13: P | C13: 10OU700 | D13: C - Sedan | E13: SB - Setback | F13: PP - Perpendicular | G13: L
B14: P | C14: 11OO100 | D14: C - Sedan | E14: SB - Setback | F14: PP - Perpendicular | G14: L
B15: P | C15: 16UU777 | D15: C - Sedan | E15: SB - Setback | F15: PP - Perpendicular | G15: L
B16: P | C16: 66GG055 | D16: C - Sedan | E16: SB - Setback | F16: PP - Perpendicular | G16: L
B17: P | C17: 50AB055 | D17: C - Sedan | E17: SB - Setback | F17: PP - Perpendicular | G17: L
B18: P | C18: no number | D18: C - Sedan | E18: SB - Setback | F18: PP - Perpendicular | G18: L
A19: 8 - 9 | B19: P | C19: 11OO100 | D19: C - Sedan | E19: SB - Setback | F19: PP - Perpendicular | G19: L
B20: P | C20: no number | D20: C - Sedan | E20: SB - Setback | F20: PP - Perpendicular | G20: L
B21: P | C21: 48ZZ008 | D21: C - Sedan | E21: SB - Setback | F21: PP - Perpendicular | G21: L
B22: P | C22: 50AB055 | D22: C - Sedan | E22: SB - Setback | F22: PP - Perpendicular | G22: L
B23: P | C23: 66GG055 | D23: C - Sedan | E23: SB - Setback | F23: PP - Perpendicular | G23: L
B24: P | C24: 16UU777 | D24: C - Sedan | E24: SB - Setback | F24: PP - Perpendicular | G24: L
B25: P | C25: 34AS959 | D25: C - Sedan | E25: SB - Setback | F25: PP - Perpendicular | G25: L
B26: P | C26: 37SG316 | D26: C - Sedan | E26: SB - Setback | F26: PP - Perpendicular | G26: L
B27: P | C27: 90XY100 | D27: C - Sedan | E27: SB - Setback | F27: PP - Perpendicular | G27: L
B28: P | C28: 13SL038 | D28: C - Sedan | E28: SB - Setback | F28: PP - Perpendicular | G28: L
B29: P | C29: 37AC595 | D29: C - Sedan | E29: SB - Setback | F29: PP - Perpendicular | G29: L
B30: P | C30: 10OU700 | D30: C - Sedan | E30: SB - Setback | F30: PP - Perpendicular | G30: L
A31: 9 - 10 | B31: P | C31: 10OU700 | D31: T - Truck | E31: SB - Setback | F31: PP - Perpendicular | G31: L
B32: P | C32: 19OO001 | D32: C - Sedan | E32: SB - Setback | F32: PP - Perpendicular | G32: L
B33: P | C33: 10TT808 | D33: C - Sedan | E33: SB - Setback | F33: PP - Perpendicular | G33: L
B34: P | C34: 90XY100 | D34: C - Sedan | E34: SB - Setback | F34: PP - Perpendicular | G34: L
B35: P | C35: 37AC595 | D35: C - Sedan | E35: SB - Setback | F35: PP - Perpendicular | G35: L
B36: P | C36: 90XH100 | D36: C - Sedan | E36: SB - Setback | F36: PP - Perpendicular | G36: L
B37: P | C37: 13SL038 | D37: C - Sedan | E37: SB - Setback | F37: PP - Perpendicular | G37: L
B38: P | C38: 37SG316 | D38: C - Sedan | E38: SB - Setback | F38: PP - Perpendicular | G38: L
B39: P | C39: 30LL677 | D39: C - Sedan | E39: SB - Setback | F39: PP - Perpendicular | G39: L
B40: P | C40: 37CW708 | D40: C - Sedan | E40: SB - Setback | F40: PP - Perpendicular | G40: L
B41: P | C41: 34AS959 | D41: C - Sedan | E41: SB - Setback | F41: PP - Perpendicular | G41: L
B42: P | C42: 16UU777 | D42: C - Sedan | E42: SB - Setback | F42: PP - Perpendicular | G42: L
...

Sheet United Data
A1: Time | B1: Zone | C1: License Number | D1: Vehicle Type | E1: Location | F1: Parking Method | G1: Legal/Illegal
A2: 7=7:00 14=14:00 midnight=00:00 & etc. | B2: Zone XXX | C2: 11XX111 | D2: C - Sedan T - Truck M - Motorcycle | E2: OS - On-Street FP - Footpath SB - Setback | F2: PA - Parallel A - 45 Degree PP - Perpendicular | G2: L - Legal I - Illegal
A3: 7 | B3: 60 | C3: 07IL007 | D3: C - Sedan | E3: SB - Setback | F3: PP - Perpendicular | G3: L
A4: 7 | B4: 60 | C4: 99PD990 | D4: C - Sedan | E4: SB - Setback | F4: PP - Perpendicular | G4: L
A5: 7 | B5: 60 | C5: 28LS242 | D5: C - Sedan | E5: SB - Setback | F5: PP - Perpendicular | G5: L
A6: 9 | B6: 60 | C6: 50WV551 | D6: C - Sedan | E6: OS - On-Street | F6: PA - Parallel | G6: L
A7: 11 | B7: 60 | C7: 37HJ375 | D7: C - Sedan | E7: OS - On-Street | F7: PA - Parallel | G7: L
A8: 11 | B8: 60 | C8: 37NF169 | D8: C - Sedan | E8: OS - On-Street | F8: PA - Parallel | G8: L
A9: 11 | B9: 60 | C9: 73DG737 | D9: C - Sedan | E9: OS - On-Street | F9: A - 45 Degree | G9: L
A10: 11 | B10: 60 | C10: 37NF169 | D10: C - Sedan | E10: OS - On-Street | F10: PA - Parallel | G10: L
A11: 11 | B11: 60 | C11: 37HJ375 | D11: C - Sedan | E11: OS - On-Street | F11: PA - Parallel | G11: L
A12: 12 | B12: 60 | C12: 37RI946 | D12: C - Sedan | E12: OS - On-Street | F12: PA - Parallel | G12: L
A13: 12 | B13: 60 | C13: 37JC072 | D13: C - Sedan | E13: OS - On-Street | F13: PA - Parallel | G13: L
A14: 13 | B14: 60 | C14: 37HJ375 | D14: C - Sedan | E14: OS - On-Street | F14: PA - Parallel | G14: L
... A1559: 22 | B1559: 69 | C1559: 13RU131 | D1559: C - Sedan | E1559: SB - Setback | F1559: A - 45 Degree | G1559: L
A1560: 7 | B1560: P | C1560: 37SG316 | D1560: C - Sedan | E1560: SB - Setback | F1560: PP - Perpendicular | G1560: L
A1561: 7 | B1561: P | C1561: 13SL038 | D1561: C - Sedan | E1561: SB - Setback | F1561: PP - Perpendicular | G1561: L
A1562: 7 | B1562: P | C1562: 37AC595 | D1562: C - Sedan | E1562: SB - Setback | F1562: PP - Perpendicular | G1562: L
A1563: 7 | B1563: P | C1563: 90XY100 | D1563: C - Sedan | E1563: SB - Setback | F1563: PP - Perpendicular | G1563: L
A1564: 7 | B1564: P | C1564: 10OU700 | D1564: C - Sedan | E1564: SB - Setback | F1564: PP - Perpendicular | G1564: L
A1565: 7 | B1565: P | C1565: 11OO100 | D1565: C - Sedan | E1565: SB - Setback | F1565: PP - Perpendicular | G1565: L
A1566: 7 | B1566: P | C1566: 16UU777 | D1566: C - Sedan | E1566: SB - Setback | F1566: PP - Perpendicular | G1566: L
A1567: 7 | B1567: P | C1567: 66GG055 | D1567: C - Sedan | E1567: SB - Setback | F1567: PP - Perpendicular | G1567: L
A1568: 7 | B1568: P | C1568: 50AB055 | D1568: C - Sedan | E1568: SB - Setback | F1568: PP - Perpendicular | G1568: L
A1569: 7 | B1569: P | C1569: no number 2 | D1569: C - Sedan | E1569: SB - Setback | F1569: PP - Perpendicular | G1569: L
A1570: 8 | B1570: P | C1570: 11OO100 | D1570: C - Sedan | E1570: SB - Setback | F1570: PP - Perpendicular | G1570: L
A1571: 8 | B1571: P | C1571: no number 3 | D1571: C - Sedan | E1571: SB - Setback | F1571: PP - Perpendicular | G1571: L
... A2150: 21 | B2150: P | C2150: no number 5 | D2150: C - Sedan | E2150: SB - Setback | F2150: PP - Perpendicular | G2150: L

Sheet ANALYSIS
A1: PARKING SURVEY ANALYSIS — MEGA MALL | F1: Zone | G1: Formal capacity
A2: Methodology replicated from "Parking Survey Sheet v5" (Komitas) ANALYSIS sheet. | F2: 60
A3: Every number below is a live formula referencing CALC Combined / CALC On-Street / CALC Off-Street, | F3: 61
A4: which derive each vehicle's hourly presence via COUNTIFS against United Data. Enter zone capacities (yellow, right). | F4: 62
F5: 63
A6: COMBINED — ALL ZONES | F6: 64
A7: Unique vehicles | C7: =COUNTA('CALC Combined'!$A$2:$A$933) -> 932 | F7: 65
A8: PARKING DURATION | F8: 66
A9: Average parking duration | C9: =AVERAGE('CALC Combined'!$T$2:$T$933) -> 1.1888412 | D9: hours | F9: 67
A10: Median parking duration | C10: =MEDIAN('CALC Combined'!$T$2:$T$933) -> 1 | D10: hours | F10: 68
A11: PARKING SPACE TURNOVER | F11: 69
A12: # parking events | C12: =SUM('CALC Combined'!$U$2:$U$933) -> 0 | F12: P (mall parking)
A13: Formal capacity | C13: =SUM(G2:G12) -> 0 | D13: (sum of zone capacities →)
A14: Turnover per parking space (incl. illegal parking) | C14: =IF($C$13=0,"",C12/C13) | D14: events per space
A15: LONG-TERM PARKING (share of vehicles by total hours parked)
A16: Parked the full survey window (17 h) | C16: =COUNTIF('CALC Combined'!$T$2:$T$933,17)/C7 -> 0
A17: Parked 16+ hours | C17: =COUNTIF('CALC Combined'!$T$2:$T$933,">=16")/C7 -> 0
A18: Parked 12+ hours | C18: =COUNTIF('CALC Combined'!$T$2:$T$933,">=12")/C7 -> 0
A20: ON-STREET — ZONES 59–69
A21: Unique vehicles | C21: =COUNTA('CALC On-Street'!$A$2:$A$727) -> 726
A22: PARKING DURATION
A23: Average parking duration | C23: =AVERAGE('CALC On-Street'!$T$2:$T$727) -> 1.1349862 | D23: hours
A24: Median parking duration | C24: =MEDIAN('CALC On-Street'!$T$2:$T$727) -> 1 | D24: hours
A25: PARKING SPACE TURNOVER
A26: # parking events | C26: =SUM('CALC On-Street'!$U$2:$U$727) -> 0
A27: Formal capacity | C27: =SUM(G2:G11) -> 0 | D27: (sum of zone capacities →)
A28: Turnover per parking space (incl. illegal parking) | C28: =IF($C$27=0,"",C26/C27) | D28: events per space
A29: LONG-TERM PARKING (share of vehicles by total hours parked)
A30: Parked the full survey window (17 h) | C30: =COUNTIF('CALC On-Street'!$T$2:$T$727,17)/C21 -> 0
A31: Parked 16+ hours | C31: =COUNTIF('CALC On-Street'!$T$2:$T$727,">=16")/C21 -> 0
A32: Parked 12+ hours | C32: =COUNTIF('CALC On-Street'!$T$2:$T$727,">=12")/C21 -> 0
A34: OFF-STREET — OFF-STREET
A35: Unique vehicles | C35: =COUNTA('CALC Off-Street'!$A$2:$A$212) -> 211
A36: PARKING DURATION
A37: Average parking duration | C37: =AVERAGE('CALC Off-Street'!$T$2:$T$212) -> 1.3601896 | D37: hours
A38: Median parking duration | C38: =MEDIAN('CALC Off-Street'!$T$2:$T$212) -> 1 | D38: hours
A39: PARKING SPACE TURNOVER
A40: # parking events | C40: =SUM('CALC Off-Street'!$U$2:$U$212) -> 0
A41: Formal capacity | C41: =G12 -> 0 | D41: (sum of zone capacities →)
A42: Turnover per parking space (incl. illegal parking) | C42: =IF($C$41=0,"",C40/C41) | D42: events per space
...

Sheet CALC Combined
A1: License Number | B1: 7 | C1: 8 | D1: 9 | E1: 10 | F1: 11 | G1: 12 | H1: 13 | I1: 14 | J1: 15 | K1: 16 | L1: 17 | M1: 18 | N1: 19 | O1: 20 | P1: 21 | Q1: 22 | R1: 23 | S1: Total hours | T1: # parking events
A2: 07IL007 | B2: =IF(COUNTIFS('United Data'!$A$3:$A$2150,B$1,'United Data'!$C$3:$C$2150,$A2)>0,1,0) -> 1 | C2: =IF(COUNTIFS('United Data'!$A$3:$A$2150,C$1,'United Data'!$C$3:$C$2150,$A2)>0,1,0) -> 1 | D2: =IF(COUNTIFS('United Data'!$A$3:$A$2150,D$1,'United Data'!$C$3:$C$2150,$A2)>0,1,0) -> 1 | E2: =IF(COUNTIFS('United Data'!$A$3:$A$2150,E$1,'United Data'!$C$3:$C$2150,$A2)>0,1,0) -> 1 | F2: =IF(COUNTIFS('United Data'!$A$3:$A$2150,F$1,'United Data'!$C$3:$C$2150,$A2)>0,1,0) -> 0 | G2: =IF(COUNTIFS('United Data'!$A$3:$A$2150,G$1,'United Data'!$C$3:$C$2150,$A2)>0,1,0) -> 1 | H2: =IF(COUNTIFS('United Data'!$A$3:$A$2150,H$1,'United Data'!$C$3:$C$2150,$A2)>0,1,0) -> 1 | I2: =IF(COUNTIFS('United Data'!$A$3:$A$2150,I$1,'United Data'!$C$3:$C$2150,$A2)>0,1,0) -> 1 | ... R2: =IF(COUNTIFS('United Data'!$A$3:$A$2150,R$1,'United Data'!$C$3:$C$2150,$A2)>0,1,0) -> 0 | S2: =SUM(B2:R2) -> 11 | T2: =B2+SUMPRODUCT(--(C2:R2>B2:Q2)) -> 2
A3: 99PD990 | B3: =IF(COUNTIFS('United Data'!$A$3:$A$2150,B$1,'United Data'!$C$3:$C$2150,$A3)>0,1,0) -> 1 | C3: =IF(COUNTIFS('United Data'!$A$3:$A$2150,C$1,'United Data'!$C$3:$C$2150,$A3)>0,1,0) -> 1 | D3: =IF(COUNTIFS('United Data'!$A$3:$A$2150,D$1,'United Data'!$C$3:$C$2150,$A3)>0,1,0) -> 1 | E3: =IF(COUNTIFS('United Data'!$A$3:$A$2150,E$1,'United Data'!$C$3:$C$2150,$A3)>0,1,0) -> 0 | F3: =IF(COUNTIFS('United Data'!$A$3:$A$2150,F$1,'United Data'!$C$3:$C$2150,$A3)>0,1,0) -> 0 | G3: =IF(COUNTIFS('United Data'!$A$3:$A$2150,G$1,'United Data'!$C$3:$C$2150,$A3)>0,1,0) -> 0 | H3: =IF(COUNTIFS('United Data'!$A$3:$A$2150,H$1,'United Data'!$C$3:$C$2150,$A3)>0,1,0) -> 0 | I3: =IF(COUNTIFS('United Data'!$A$3:$A$2150,I$1,'United Data'!$C$3:$C$2150,$A3)>0,1,0) -> 0 | ... R3: =IF(COUNTIFS('United Data'!$A$3:$A$2150,R$1,'United Data'!$C$3:$C$2150,$A3)>0,1,0) -> 0 | S3: =SUM(B3:R3) -> 3 | T3: =B3+SUMPRODUCT(--(C3:R3>B3:Q3)) -> 1
A4: 28LS242 | B4: =IF(COUNTIFS('United Data'!$A$3:$A$2150,B$1,'United Data'!$C$3:$C$2150,$A4)>0,1,0) -> 1 | C4: =IF(COUNTIFS('United Data'!$A$3:$A$2150,C$1,'United Data'!$C$3:$C$2150,$A4)>0,1,0) -> 1 | D4: =IF(COUNTIFS('United Data'!$A$3:$A$2150,D$1,'United Data'!$C$3:$C$2150,$A4)>0,1,0) -> 1 | E4: =IF(COUNTIFS('United Data'!$A$3:$A$2150,E$1,'United Data'!$C$3:$C$2150,$A4)>0,1,0) -> 1 | F4: =IF(COUNTIFS('United Data'!$A$3:$A$2150,F$1,'United Data'!$C$3:$C$2150,$A4)>0,1,0) -> 0 | G4: =IF(COUNTIFS('United Data'!$A$3:$A$2150,G$1,'United Data'!$C$3:$C$2150,$A4)>0,1,0) -> 0 | H4: =IF(COUNTIFS('United Data'!$A$3:$A$2150,H$1,'United Data'!$C$3:$C$2150,$A4)>0,1,0) -> 0 | I4: =IF(COUNTIFS('United Data'!$A$3:$A$2150,I$1,'United Data'!$C$3:$C$2150,$A4)>0,1,0) -> 0 | ... R4: =IF(COUNTIFS('United Data'!$A$3:$A$2150,R$1,'United Data'!$C$3:$C$2150,$A4)>0,1,0) -> 0 | S4: =SUM(B4:R4) -> 4 | T4: =B4+SUMPRODUCT(--(C4:R4>B4:Q4)) -> 1
A5: 50WV551 | B5: =IF(COUNTIFS('United Data'!$A$3:$A$2150,B$1,'United Data'!$C$3:$C$2150,$A5)>0,1,0) -> 0 | C5: =IF(COUNTIFS('United Data'!$A$3:$A$2150,C$1,'United Data'!$C$3:$C$2150,$A5)>0,1,0) -> 0 | D5: =IF(COUNTIFS('United Data'!$A$3:$A$2150,D$1,'United Data'!$C$3:$C$2150,$A5)>0,1,0) -> 1 | E5: =IF(COUNTIFS('United Data'!$A$3:$A$2150,E$1,'United Data'!$C$3:$C$2150,$A5)>0,1,0) -> 0 | F5: =IF(COUNTIFS('United Data'!$A$3:$A$2150,F$1,'United Data'!$C$3:$C$2150,$A5)>0,1,0) -> 0 | G5: =IF(COUNTIFS('United Data'!$A$3:$A$2150,G$1,'United Data'!$C$3:$C$2150,$A5)>0,1,0) -> 0 | H5: =IF(COUNTIFS('United Data'!$A$3:$A$2150,H$1,'United Data'!$C$3:$C$2150,$A5)>0,1,0) -> 0 | I5: =IF(COUNTIFS('United Data'!$A$3:$A$2150,I$1,'United Data'!$C$3:$C$2150,$A5)>0,1,0) -> 0 | ... R5: =IF(COUNTIFS('United Data'!$A$3:$A$2150,R$1,'United Data'!$C$3:$C$2150,$A5)>0,1,0) -> 0 | S5: =SUM(B5:R5) -> 1 | T5: =B5+SUMPRODUCT(--(C5:R5>B5:Q5)) -> 1
A6: 37HJ375 | B6: =IF(COUNTIFS('United Data'!$A$3:$A$2150,B$1,'United Data'!$C$3:$C$2150,$A6)>0,1,0) -> 0 | C6: =IF(COUNTIFS('United Data'!$A$3:$A$2150,C$1,'United Data'!$C$3:$C$2150,$A6)>0,1,0) -> 0 | D6: =IF(COUNTIFS('United Data'!$A$3:$A$2150,D$1,'United Data'!$C$3:$C$2150,$A6)>0,1,0) -> 0 | E6: =IF(COUNTIFS('United Data'!$A$3:$A$2150,E$1,'United Data'!$C$3:$C$2150,$A6)>0,1,0) -> 1 | F6: =IF(COUNTIFS('United Data'!$A$3:$A$2150,F$1,'United Data'!$C$3:$C$2150,$A6)>0,1,0) -> 1 | G6: =IF(COUNTIFS('United Data'!$A$3:$A$2150,G$1,'United Data'!$C$3:$C$2150,$A6)>0,1,0) -> 0 | H6: =IF(COUNTIFS('United Data'!$A$3:$A$2150,H$1,'United Data'!$C$3:$C$2150,$A6)>0,1,0) -> 1 | I6: =IF(COUNTIFS('United Data'!$A$3:$A$2150,I$1,'United Data'!$C$3:$C$2150,$A6)>0,1,0) -> 1 | ... R6: =IF(COUNTIFS('United Data'!$A$3:$A$2150,R$1,'United Data'!$C$3:$C$2150,$A6)>0,1,0) -> 0 | S6: =SUM(B6:R6) -> 8 | T6: =B6+SUMPRODUCT(--(C6:R6>B6:Q6)) -> 4
A7: 37NF169 | B7: =IF(COUNTIFS('United Data'!$A$3:$A$2150,B$1,'United Data'!$C$3:$C$2150,$A7)>0,1,0) -> 0 | C7: =IF(COUNTIFS('United Data'!$A$3:$A$2150,C$1,'United Data'!$C$3:$C$2150,$A7)>0,1,0) -> 0 | D7: =IF(COUNTIFS('United Data'!$A$3:$A$2150,D$1,'United Data'!$C$3:$C$2150,$A7)>0,1,0) -> 0 | E7: =IF(COUNTIFS('United Data'!$A$3:$A$2150,E$1,'United Data'!$C$3:$C$2150,$A7)>0,1,0) -> 0 | F7: =IF(COUNTIFS('United Data'!$A$3:$A$2150,F$1,'United Data'!$C$3:$C$2150,$A7)>0,1,0) -> 1 | G7: =IF(COUNTIFS('United Data'!$A$3:$A$2150,G$1,'United Data'!$C$3:$C$2150,$A7)>0,1,0) -> 0 | H7: =IF(COUNTIFS('United Data'!$A$3:$A$2150,H$1,'United Data'!$C$3:$C$2150,$A7)>0,1,0) -> 0 | I7: =IF(COUNTIFS('United Data'!$A$3:$A$2150,I$1,'United Data'!$C$3:$C$2150,$A7)>0,1,0) -> 0 | ... R7: =IF(COUNTIFS('United Data'!$A$3:$A$2150,R$1,'United Data'!$C$3:$C$2150,$A7)>0,1,0) -> 0 | S7: =SUM(B7:R7) -> 1 | T7: =B7+SUMPRODUCT(--(C7:R7>B7:Q7)) -> 1
A8: 73DG737 | B8: =IF(COUNTIFS('United Data'!$A$3:$A$2150,B$1,'United Data'!$C$3:$C$2150,$A8)>0,1,0) -> 0 | C8: =IF(COUNTIFS('United Data'!$A$3:$A$2150,C$1,'United Data'!$C$3:$C$2150,$A8)>0,1,0) -> 0 | D8: =IF(COUNTIFS('United Data'!$A$3:$A$2150,D$1,'United Data'!$C$3:$C$2150,$A8)>0,1,0) -> 0 | E8: =IF(COUNTIFS('United Data'!$A$3:$A$2150,E$1,'United Data'!$C$3:$C$2150,$A8)>0,1,0) -> 0 | F8: =IF(COUNTIFS('United Data'!$A$3:$A$2150,F$1,'United Data'!$C$3:$C$2150,$A8)>0,1,0) -> 1 | G8: =IF(COUNTIFS('United Data'!$A$3:$A$2150,G$1,'United Data'!$C$3:$C$2150,$A8)>0,1,0) -> 0 | H8: =IF(COUNTIFS('United Data'!$A$3:$A$2150,H$1,'United Data'!$C$3:$C$2150,$A8)>0,1,0) -> 0 | I8: =IF(COUNTIFS('United Data'!$A$3:$A$2150,I$1,'United Data'!$C$3:$C$2150,$A8)>0,1,0) -> 0 | ... R8: =IF(COUNTIFS('United Data'!$A$3:$A$2150,R$1,'United Data'!$C$3:$C$2150,$A8)>0,1,0) -> 0 | S8: =SUM(B8:R8) -> 1 | T8: =B8+SUMPRODUCT(--(C8:R8>B8:Q8)) -> 1
A9: 37RI946 | B9: =IF(COUNTIFS('United Data'!$A$3:$A$2150,B$1,'United Data'!$C$3:$C$2150,$A9)>0,1,0) -> 0 | C9: =IF(COUNTIFS('United Data'!$A$3:$A$2150,C$1,'United Data'!$C$3:$C$2150,$A9)>0,1,0) -> 0 | D9: =IF(COUNTIFS('United Data'!$A$3:$A$2150,D$1,'United Data'!$C$3:$C$2150,$A9)>0,1,0) -> 0 | E9: =IF(COUNTIFS('United Data'!$A$3:$A$2150,E$1,'United Data'!$C$3:$C$2150,$A9)>0,1,0) -> 0 | F9: =IF(COUNTIFS('United Data'!$A$3:$A$2150,F$1,'United Data'!$C$3:$C$2150,$A9)>0,1,0) -> 0 | G9: =IF(COUNTIFS('United Data'!$A$3:$A$2150,G$1,'United Data'!$C$3:$C$2150,$A9)>0,1,0) -> 1 | H9: =IF(COUNTIFS('United Data'!$A$3:$A$2150,H$1,'United Data'!$C$3:$C$2150,$A9)>0,1,0) -> 0 | I9: =IF(COUNTIFS('United Data'!$A$3:$A$2150,I$1,'United Data'!$C$3:$C$2150,$A9)>0,1,0) -> 0 | ... R9: =IF(COUNTIFS('United Data'!$A$3:$A$2150,R$1,'United Data'!$C$3:$C$2150,$A9)>0,1,0) -> 0 | S9: =SUM(B9:R9) -> 1 | T9: =B9+SUMPRODUCT(--(C9:R9>B9:Q9)) -> 1
A10: 37JC072 | B10: =IF(COUNTIFS('United Data'!$A$3:$A$2150,B$1,'United Data'!$C$3:$C$2150,$A10)>0,1,0) -> 0 | C10: =IF(COUNTIFS('United Data'!$A$3:$A$2150,C$1,'United Data'!$C$3:$C$2150,$A10)>0,1,0) -> 0 | D10: =IF(COUNTIFS('United Data'!$A$3:$A$2150,D$1,'United Data'!$C$3:$C$2150,$A10)>0,1,0) -> 0 | E10: =IF(COUNTIFS('United Data'!$A$3:$A$2150,E$1,'United Data'!$C$3:$C$2150,$A10)>0,1,0) -> 0 | F10: =IF(COUNTIFS('United Data'!$A$3:$A$2150,F$1,'United Data'!$C$3:$C$2150,$A10)>0,1,0) -> 0 | G10: =IF(COUNTIFS('United Data'!$A$3:$A$2150,G$1,'United Data'!$C$3:$C$2150,$A10)>0,1,0) -> 1 | H10: =IF(COUNTIFS('United Data'!$A$3:$A$2150,H$1,'United Data'!$C$3:$C$2150,$A10)>0,1,0) -> 0 | I10: =IF(COUNTIFS('United Data'!$A$3:$A$2150,I$1,'United Data'!$C$3:$C$2150,$A10)>0,1,0) -> 0 | ... R10: =IF(COUNTIFS('United Data'!$A$3:$A$2150,R$1,'United Data'!$C$3:$C$2150,$A10)>0,1,0) -> 0 | S10: =SUM(B10:R10) -> 1 | T10: =B10+SUMPRODUCT(--(C10:R10>B10:Q10)) -> 1
A11: 14VU114 | B11: =IF(COUNTIFS('United Data'!$A$3:$A$2150,B$1,'United Data'!$C$3:$C$2150,$A11)>0,1,0) -> 0 | C11: =IF(COUNTIFS('United Data'!$A$3:$A$2150,C$1,'United Data'!$C$3:$C$2150,$A11)>0,1,0) -> 0 | D11: =IF(COUNTIFS('United Data'!$A$3:$A$2150,D$1,'United Data'!$C$3:$C$2150,$A11)>0,1,0) -> 0 | E11: =IF(COUNTIFS('United Data'!$A$3:$A$2150,E$1,'United Data'!$C$3:$C$2150,$A11)>0,1,0) -> 0 | F11: =IF(COUNTIFS('United Data'!$A$3:$A$2150,F$1,'United Data'!$C$3:$C$2150,$A11)>0,1,0) -> 0 | G11: =IF(COUNTIFS('United Data'!$A$3:$A$2150,G$1,'United Data'!$C$3:$C$2150,$A11)>0,1,0) -> 0 | H11: =IF(COUNTIFS('United Data'!$A$3:$A$2150,H$1,'United Data'!$C$3:$C$2150,$A11)>0,1,0) -> 0 | I11: =IF(COUNTIFS('United Data'!$A$3:$A$2150,I$1,'United Data'!$C$3:$C$2150,$A11)>0,1,0) -> 0 | ... R11: =IF(COUNTIFS('United Data'!$A$3:$A$2150,R$1,'United Data'!$C$3:$C$2150,$A11)>0,1,0) -> 0 | S11: =SUM(B11:R11) -> 1 | T11: =B11+SUMPRODUCT(--(C11:R11>B11:Q11)) -> 1
A12: 99NM929 | B12: =IF(COUNTIFS('United Data'!$A$3:$A$2150,B$1,'United Data'!$C$3:$C$2150,$A12)>0,1,0) -> 0 | C12: =IF(COUNTIFS('United Data'!$A$3:$A$2150,C$1,'United Data'!$C$3:$C$2150,$A12)>0,1,0) -> 0 | D12: =IF(COUNTIFS('United Data'!$A$3:$A$2150,D$1,'United Data'!$C$3:$C$2150,$A12)>0,1,0) -> 0 | E12: =IF(COUNTIFS('United Data'!$A$3:$A$2150,E$1,'United Data'!$C$3:$C$2150,$A12)>0,1,0) -> 0 | F12: =IF(COUNTIFS('United Data'!$A$3:$A$2150,F$1,'United Data'!$C$3:$C$2150,$A12)>0,1,0) -> 0 | G12: =IF(COUNTIFS('United Data'!$A$3:$A$2150,G$1,'United Data'!$C$3:$C$2150,$A12)>0,1,0) -> 0 | H12: =IF(COUNTIFS('United Data'!$A$3:$A$2150,H$1,'United Data'!$C$3:$C$2150,$A12)>0,1,0) -> 0 | I12: =IF(COUNTIFS('United Data'!$A$3:$A$2150,I$1,'United Data'!$C$3:$C$2150,$A12)>0,1,0) -> 0 | ... R12: =IF(COUNTIFS('United Data'!$A$3:$A$2150,R$1,'United Data'!$C$3:$C$2150,$A12)>0,1,0) -> 0 | S12: =SUM(B12:R12) -> 1 | T12: =B12+SUMPRODUCT(--(C12:R12>B12:Q12)) -> 1
A13: 37NJ375 | B13: =IF(COUNTIFS('United Data'!$A$3:$A$2150,B$1,'United Data'!$C$3:$C$2150,$A13)>0,1,0) -> 0 | C13: =IF(COUNTIFS('United Data'!$A$3:$A$2150,C$1,'United Data'!$C$3:$C$2150,$A13)>0,1,0) -> 0 | D13: =IF(COUNTIFS('United Data'!$A$3:$A$2150,D$1,'United Data'!$C$3:$C$2150,$A13)>0,1,0) -> 0 | E13: =IF(COUNTIFS('United Data'!$A$3:$A$2150,E$1,'United Data'!$C$3:$C$2150,$A13)>0,1,0) -> 0 | F13: =IF(COUNTIFS('United Data'!$A$3:$A$2150,F$1,'United Data'!$C$3:$C$2150,$A13)>0,1,0) -> 0 | G13: =IF(COUNTIFS('United Data'!$A$3:$A$2150,G$1,'United Data'!$C$3:$C$2150,$A13)>0,1,0) -> 0 | H13: =IF(COUNTIFS('United Data'!$A$3:$A$2150,H$1,'United Data'!$C$3:$C$2150,$A13)>0,1,0) -> 0 | I13: =IF(COUNTIFS('United Data'!$A$3:$A$2150,I$1,'United Data'!$C$3:$C$2150,$A13)>0,1,0) -> 0 | ... R13: =IF(COUNTIFS('United Data'!$A$3:$A$2150,R$1,'United Data'!$C$3:$C$2150,$A13)>0,1,0) -> 0 | S13: =SUM(B13:R13) -> 2 | T13: =B13+SUMPRODUCT(--(C13:R13>B13:Q13)) -> 2
